Workbook

Sheet 브릭샌드
B1: 뷰티앤바이트글로벌㈜ | C1: 브릭샌드 | D1: 756-86-02482 | E1: 002482
M2: 1048656659 | N2: 119948 | O2: 033138 | P2: 007072 | Q2: 037726 | R2: 015419 | S2: 072014 | T2: 045602 | U2: 054231
A3: 일 자 | B3: 현금매출액 | C3: 전자화폐 | D3: 카드매출액 | E3: 할인액 | F3: 총매출액 | G3: 입금기한 | H3: 입금일 | I3: 입금액 | J3: 잔액 | K3: 연체일 | L3: 연체료 | M3: 하나 | N3: 위쳇페이 | O3: KB국민 | P3: NH농협 | Q3: 비씨 | R3: 현대 | S3: 신한 | T3: 삼성 | U3: 롯데 | V3: 합계
A4: 46082 | D4: =V4 -> 0 | F4: =+B4+D4+E4+C4 -> 0 | J4: =+B4-I4 -> 0 | V4: =SUM(M4:U4) -> 0
A5: 46083 | D5: =V5 -> 0 | F5: =+B5+D5+E5+C5 -> 0 | J5: =+B5-I5 -> 0 | V5: =SUM(M5:U5) -> 0
A6: 46084 | D6: =V6 -> 0 | F6: =+B6+D6+E6+C6 -> 0 | J6: =+B6-I6 -> 0 | V6: =SUM(M6:U6) -> 0
A7: 46085 | D7: =V7 -> 0 | F7: =+B7+D7+E7+C7 -> 0 | J7: =+B7-I7 -> 0 | V7: =SUM(M7:U7) -> 0
A8: 46086 | D8: =V8 -> 0 | F8: =+B8+D8+E8+C8 -> 0 | J8: =+B8-I8 -> 0 | V8: =SUM(M8:U8) -> 0
A9: 46087 | D9: =V9 -> 0 | F9: =+B9+D9+E9+C9 -> 0 | J9: =+B9-I9 -> 0 | V9: =SUM(M9:U9) -> 0
A10: 46088 | D10: =V10 -> 0 | F10: =+B10+D10+E10+C10 -> 0 | J10: =+B10-I10 -> 0 | V10: =SUM(M10:U10) -> 0
A11: 46089 | D11: =V11 -> 0 | F11: =+B11+D11+E11+C11 -> 0 | J11: =+B11-I11 -> 0 | V11: =SUM(M11:U11) -> 0
A12: 46090 | D12: =V12 -> 0 | F12: =+B12+D12+E12+C12 -> 0 | J12: =+B12-I12 -> 0 | V12: =SUM(M12:U12) -> 0
A13: 46091 | D13: =V13 -> 0 | F13: =+B13+D13+E13+C13 -> 0 | J13: =+B13-I13 -> 0 | V13: =SUM(M13:U13) -> 0
A14: 46092 | D14: =V14 -> 0 | F14: =+B14+D14+E14+C14 -> 0 | J14: =+B14-I14 -> 0 | V14: =SUM(M14:U14) -> 0
A15: 46093 | D15: =V15 -> 0 | F15: =+B15+D15+E15+C15 -> 0 | J15: =+B15-I15 -> 0 | V15: =SUM(M15:U15) -> 0
... A34: 46112 | D34: =V34 -> 0 | F34: =+B34+D34+E34+C34 -> 0 | J34: =+B34-I34 -> 0 | V34: =SUM(M34:U34) -> 0
A35: 합 계 | B35: =SUM(B4:B34) -> 0 | C35: =SUM(C4:C34) -> 0 | D35: =SUM(D4:D34) -> 0 | E35: =SUM(E4:E34) -> 0 | F35: =+B35+D35+E35 -> 0 | G35: =SUM(G4:G34) -> 0 | H35: =SUM(H4:H34) -> 0 | I35: =SUM(I4:I34) -> 0 | J35: =SUM(J4:J34) -> 0 | L35: =SUM(L4:L34) -> 0 | M35: =SUM(M4:M34) -> 0 | N35: =SUM(N4:N34) -> 0 | O35: =SUM(O4:O34) -> 0 | P35: =SUM(P4:P34) -> 0 | Q35: =SUM(Q4:Q34) -> 0 | R35: =SUM(R4:R34) -> 0 | S35: =SUM(S4:S34) -> 0 | ... V35: =SUM(V4:V34) -> 0
A38: 입금 전에 해당 매출액 정산지 메일 전송 bricksand@naver.com
B39: 수수료율 다시 확인하기 | F39: 임대을매출 | G39: =E35 -> 0 | H39: 임대을매출원가 | I39: =B45 -> 0
A40: 수수료율 | B40: 0.14 | C40: 최저 | F40: 임대을매출원가 | G40: =B45 -> 0 | H40: 임대을매출_할인 | I40: =B46 -> 0
A41: 임대료 | B41: =ROUND(B43/1.1,0) -> 0 | C41: 13000000 | H41: 임대을매출_수수료 | I41: =B41 -> 0
A42: VAT | B42: =+B43-B41 -> 0 | C42: =C41*0.1 -> 1300000 | H42: 예수부가세 | I42: =B42 -> 0
A43: 합계 | B43: =E35*B40 -> 0 | C43: =C41+C42 -> 14300000 | H43: 미지급금 | I43: =B47 -> 0
H44: 미수금 | I44: =B48 -> 0
A45: 매출원가 | B45: =E35-B41 -> 0 | G45: =SUM(G39:G44) -> 0 | I45: =SUM(I39:I44) -> 0
A46: 할인 | B46: =D35 -> 0
A47: 미지급금 | B47: =C35-B43 -> 0
A48: 미수금 | B48: =B35 -> 0

Sheet 태극당광장
B1: 태극당서울역광장점 | C1: 태극당서울역광장점 | D1: 895-85-01670 | E1: 001670
M2: 1048656659 | N2: 119948 | O2: 033138 | P2: 007072 | Q2: 037726 | R2: 015419 | S2: 072014 | T2: 045602 | U2: 054231
A3: 일 자 | B3: 현금매출액 | C3: 전자화폐 | D3: 카드매출액 | E3: 할인액 | F3: 총매출액 | G3: 입금기한 | H3: 입금일 | I3: 입금액 | J3: 잔액 | K3: 연체일 | L3: 연체료 | M3: 하나 | N3: 위쳇페이 | O3: KB국민 | P3: NH농협 | Q3: 비씨 | R3: 현대 | S3: 신한 | T3: 삼성 | U3: 롯데 | V3: 합계
A4: 46082 | D4: =V4 -> 0 | F4: =+B4+D4+E4+C4 -> 0 | J4: =+B4-I4 -> 0 | V4: =SUM(M4:U4) -> 0
A5: 46083 | D5: =V5 -> 0 | F5: =+B5+D5+E5+C5 -> 0 | J5: =+B5-I5 -> 0 | V5: =SUM(M5:U5) -> 0
A6: 46084 | D6: =V6 -> 0 | F6: =+B6+D6+E6+C6 -> 0 | J6: =+B6-I6 -> 0 | V6: =SUM(M6:U6) -> 0
A7: 46085 | D7: =V7 -> 0 | F7: =+B7+D7+E7+C7 -> 0 | J7: =+B7-I7 -> 0 | V7: =SUM(M7:U7) -> 0
A8: 46086 | D8: =V8 -> 0 | F8: =+B8+D8+E8+C8 -> 0 | J8: =+B8-I8 -> 0 | V8: =SUM(M8:U8) -> 0
A9: 46087 | D9: =V9 -> 0 | F9: =+B9+D9+E9+C9 -> 0 | J9: =+B9-I9 -> 0 | V9: =SUM(M9:U9) -> 0
A10: 46088 | D10: =V10 -> 0 | F10: =+B10+D10+E10+C10 -> 0 | J10: =+B10-I10 -> 0 | V10: =SUM(M10:U10) -> 0
A11: 46089 | D11: =V11 -> 0 | F11: =+B11+D11+E11+C11 -> 0 | J11: =+B11-I11 -> 0 | V11: =SUM(M11:U11) -> 0
A12: 46090 | D12: =V12 -> 0 | F12: =+B12+D12+E12+C12 -> 0 | J12: =+B12-I12 -> 0 | V12: =SUM(M12:U12) -> 0
A13: 46091 | D13: =V13 -> 0 | F13: =+B13+D13+E13+C13 -> 0 | J13: =+B13-I13 -> 0 | V13: =SUM(M13:U13) -> 0
A14: 46092 | D14: =V14 -> 0 | F14: =+B14+D14+E14+C14 -> 0 | J14: =+B14-I14 -> 0 | V14: =SUM(M14:U14) -> 0
A15: 46093 | D15: =V15 -> 0 | F15: =+B15+D15+E15+C15 -> 0 | J15: =+B15-I15 -> 0 | V15: =SUM(M15:U15) -> 0
... A34: 46112 | D34: =V34 -> 0 | F34: =+B34+D34+E34+C34 -> 0 | J34: =+B34-I34 -> 0 | V34: =SUM(M34:U34) -> 0
A35: 합 계 | B35: =SUM(B4:B34) -> 0 | C35: =SUM(C4:C34) -> 0 | D35: =SUM(D4:D34) -> 0 | E35: =SUM(E4:E34) -> 0 | F35: =+B35+D35+E35 -> 0 | G35: =SUM(G4:G34) -> 0 | H35: =SUM(H4:H34) -> 0 | I35: =SUM(I4:I34) -> 0 | J35: =SUM(J4:J34) -> 0 | L35: =SUM(L4:L34) -> 0 | M35: =SUM(M4:M34) -> 0 | N35: =SUM(N4:N34) -> 0 | O35: =SUM(O4:O34) -> 0 | P35: =SUM(P4:P34) -> 0 | Q35: =SUM(Q4:Q34) -> 0 | R35: =SUM(R4:R34) -> 0 | S35: =SUM(S4:S34) -> 0 | ... V35: =SUM(V4:V34) -> 0
A38: 임대보증금 | B38: 50000000 | D38: 111,000,000원으로 바뀜(09.30입금할 예정)
B40: 25.09.10~26.09.09
A41: 수수료율 | B41: 0.19 | C41: MRG
A42: 임대료 | B42: =ROUND(B44/1.1,0) -> 0 | C42: =17200000+1300000 -> 18500000
A43: VAT | B43: =+B44-B42 -> 0 | C43: =C42/10 -> 1850000
A44: 합계 | B44: =ROUND(E35*B41,0) -> 0 | C44: =C42+C43 -> 20350000
A46: 매출원가 | B46: =E35-B42 -> 0 | D46: 임대을매출 | E46: =E35 -> 0 | F46: 임대을매출원가 | G46: =B46 -> 0
A47: 미지급금 | B47: =B35+C35-B44 -> 0 | D47: 임대을매출원가 | E47: =B46 -> 0 | F47: 임대을매출_할인 | G47: =D35 -> 0
F48: 임대을매출_수수료 | G48: =B42 -> 0
B49: 매니점님 번호 | F49: 예수부가세 | G49: =B43 -> 0
B50: 010-7627-3054 | F50: 미지급금 | G50: =B47 -> 0
B51: 25.12월 기준
E52: =SUM(E46:E51) -> 0 | G52: =SUM(G46:G51) -> 0

Sheet 금옥당
B1: ㈜마켓랩 | C1: 금옥당 | D1: 128-86-37978 | E1: 037978
M2: 1048656659 | N2: 119948 | O2: 033138 | P2: 007072 | Q2: 037726 | R2: 015419 | S2: 072014 | T2: 045602 | U2: 054231
A3: 일 자 | B3: 현금매출액 | C3: 전자화폐 | D3: 카드매출액 | E3: 할인액 | F3: 총매출액 | G3: 입금기한 | H3: 입금일 | I3: 입금액 | J3: 잔액 | K3: 연체일 | L3: 연체료 | M3: 하나 | N3: 위쳇페이 | O3: KB국민 | P3: NH농협 | Q3: 비씨 | R3: 현대 | S3: 신한 | T3: 삼성 | U3: 롯데 | V3: 합계
A4: 46082 | D4: =V4 -> 0 | F4: =+B4+D4+E4+C4 -> 0 | J4: =+B4-I4 -> 0 | V4: =SUM(M4:U4) -> 0
A5: 46083 | D5: =V5 -> 0 | F5: =+B5+D5+E5+C5 -> 0 | J5: =+B5-I5 -> 0 | V5: =SUM(M5:U5) -> 0
A6: 46084 | D6: =V6 -> 0 | F6: =+B6+D6+E6+C6 -> 0 | J6: =+B6-I6 -> 0 | V6: =SUM(M6:U6) -> 0
A7: 46085 | D7: =V7 -> 0 | F7: =+B7+D7+E7+C7 -> 0 | J7: =+B7-I7 -> 0 | V7: =SUM(M7:U7) -> 0
A8: 46086 | D8: =V8 -> 0 | F8: =+B8+D8+E8+C8 -> 0 | J8: =+B8-I8 -> 0 | V8: =SUM(M8:U8) -> 0
A9: 46087 | D9: =V9 -> 0 | F9: =+B9+D9+E9+C9 -> 0 | J9: =+B9-I9 -> 0 | V9: =SUM(M9:U9) -> 0
A10: 46088 | D10: =V10 -> 0 | F10: =+B10+D10+E10+C10 -> 0 | J10: =+B10-I10 -> 0 | V10: =SUM(M10:U10) -> 0
A11: 46089 | D11: =V11 -> 0 | F11: =+B11+D11+E11+C11 -> 0 | J11: =+B11-I11 -> 0 | V11: =SUM(M11:U11) -> 0
A12: 46090 | D12: =V12 -> 0 | F12: =+B12+D12+E12+C12 -> 0 | J12: =+B12-I12 -> 0 | V12: =SUM(M12:U12) -> 0
A13: 46091 | D13: =V13 -> 0 | F13: =+B13+D13+E13+C13 -> 0 | J13: =+B13-I13 -> 0 | V13: =SUM(M13:U13) -> 0
A14: 46092 | D14: =V14 -> 0 | F14: =+B14+D14+E14+C14 -> 0 | J14: =+B14-I14 -> 0 | V14: =SUM(M14:U14) -> 0
A15: 46093 | D15: =V15 -> 0 | F15: =+B15+D15+E15+C15 -> 0 | J15: =+B15-I15 -> 0 | V15: =SUM(M15:U15) -> 0
... A34: 46112 | D34: =V34 -> 0 | F34: =+B34+D34+E34+C34 -> 0 | J34: =+B34-I34 -> 0 | V34: =SUM(M34:U34) -> 0
A35: 합 계 | B35: =SUM(B4:B34) -> 0 | C35: =SUM(C4:C34) -> 0 | D35: =SUM(D4:D34) -> 0 | E35: =SUM(E4:E34) -> 0 | F35: =+B35+D35+E35 -> 0 | G35: =SUM(G4:G34) -> 0 | H35: =SUM(H4:H34) -> 0 | I35: =SUM(I4:I34) -> 0 | J35: =SUM(J4:J34) -> 0 | L35: =SUM(L4:L34) -> 0 | M35: =SUM(M4:M34) -> 0 | N35: =SUM(N4:N34) -> 0 | O35: =SUM(O4:O34) -> 0 | P35: =SUM(P4:P34) -> 0 | Q35: =SUM(Q4:Q34) -> 0 | R35: =SUM(R4:R34) -> 0 | S35: =SUM(S4:S34) -> 0 | ... V35: =SUM(V4:V34) -> 0
A37: 임대보증금 | B37: 1억(보증보험대체)
B39: 26.04.01~27.03.06
A40: 수수료율 | B40: 0.19 | C40: MRG
A41: 임대료 | B41: =ROUND(B43/1.1,0) -> 0 | C41: 10222000
A42: VAT | B42: =+B43-B41 -> 0 | C42: 1022200
A43: 합계 | B43: =ROUND(E34*B40,0) -> 0 | C43: =C41+C42 -> 11244200
A45: 매출원가 | B45: =E34-B41 -> 0 | D45: 임대을매출 | E45: =E34 -> 0 | F45: 임대을매출원가 | G45: =B45 -> 0
A46: 미지급금 | B46: =B34+C34-B43 -> 0 | D46: 임대을매출원가 | E46: =B45 -> 0 | F46: 임대을매출_할인 | G46: =D34 -> 0
F47: 임대을매출_수수료 | G47: =B41 -> 0
F48: 예수부가세 | G48: =B42 -> 0
F49: 미지급금 | G49: =B46 -> 0
E51: =SUM(E45:E50) -> 0 | G51: =SUM(G45:G50) -> 0

Sheet 다복집
B1: 다복집 | C1: 다복집 | D1: 113-04-76779 | E1: 076779
M2: 1048656659 | N2: 119948 | O2: 033138 | P2: 007072 | Q2: 037726 | R2: 015419 | S2: 072014 | T2: 045602 | U2: 054231
A3: 일 자 | B3: 현금매출액 | C3: 전자화폐 | D3: 카드매출액 | E3: 할인액 | F3: 총매출액 | G3: 입금기한 | H3: 입금일 | I3: 입금액 | J3: 잔액 | K3: 연체일 | L3: 연체료 | M3: 하나 | N3: 위쳇페이 | O3: KB국민 | P3: NH농협 | Q3: 비씨 | R3: 현대 | S3: 신한 | T3: 삼성 | U3: 롯데 | V3: 합계
A4: 46082 | D4: =V4 -> 0 | F4: =+B4+D4+E4+C4 -> 0 | J4: =+B4-I4 -> 0 | V4: =SUM(M4:U4) -> 0
A5: 46083 | D5: =V5 -> 0 | F5: =+B5+D5+E5+C5 -> 0 | J5: =+B5-I5 -> 0 | V5: =SUM(M5:U5) -> 0
A6: 46084 | D6: =V6 -> 0 | F6: =+B6+D6+E6+C6 -> 0 | J6: =+B6-I6 -> 0 | V6: =SUM(M6:U6) -> 0
A7: 46085 | D7: =V7 -> 0 | F7: =+B7+D7+E7+C7 -> 0 | J7: =+B7-I7 -> 0 | V7: =SUM(M7:U7) -> 0
A8: 46086 | D8: =V8 -> 0 | F8: =+B8+D8+E8+C8 -> 0 | J8: =+B8-I8 -> 0 | V8: =SUM(M8:U8) -> 0
A9: 46087 | D9: =V9 -> 0 | F9: =+B9+D9+E9+C9 -> 0 | J9: =+B9-I9 -> 0 | V9: =SUM(M9:U9) -> 0
A10: 46088 | D10: =V10 -> 0 | F10: =+B10+D10+E10+C10 -> 0 | J10: =+B10-I10 -> 0 | V10: =SUM(M10:U10) -> 0
A11: 46089 | D11: =V11 -> 0 | F11: =+B11+D11+E11+C11 -> 0 | J11: =+B11-I11 -> 0 | V11: =SUM(M11:U11) -> 0
A12: 46090 | D12: =V12 -> 0 | F12: =+B12+D12+E12+C12 -> 0 | J12: =+B12-I12 -> 0 | V12: =SUM(M12:U12) -> 0
A13: 46091 | D13: =V13 -> 0 | F13: =+B13+D13+E13+C13 -> 0 | J13: =+B13-I13 -> 0 | V13: =SUM(M13:U13) -> 0
A14: 46092 | D14: =V14 -> 0 | F14: =+B14+D14+E14+C14 -> 0 | J14: =+B14-I14 -> 0 | V14: =SUM(M14:U14) -> 0
A15: 46093 | D15: =V15 -> 0 | F15: =+B15+D15+E15+C15 -> 0 | J15: =+B15-I15 -> 0 | V15: =SUM(M15:U15) -> 0
... A34: 46112 | D34: =V34 -> 0 | F34: =+B34+D34+E34+C34 -> 0 | J34: =+B34-I34 -> 0 | V34: =SUM(M34:U34) -> 0
A35: 합 계 | B35: =SUM(B4:B34) -> 0 | C35: =SUM(C4:C34) -> 0 | D35: =SUM(D4:D34) -> 0 | E35: =SUM(E4:E34) -> 0 | F35: =+B35+D35+E35 -> 0 | G35: =SUM(G4:G34) -> 0 | H35: =SUM(H4:H34) -> 0 | I35: =SUM(I4:I34) -> 0 | J35: =SUM(J4:J34) -> 0 | L35: =SUM(L4:L34) -> 0 | M35: =SUM(M4:M34) -> 0 | N35: =SUM(N4:N34) -> 0 | O35: =SUM(O4:O34) -> 0 | P35: =SUM(P4:P34) -> 0 | Q35: =SUM(Q4:Q34) -> 0 | R35: =SUM(R4:R34) -> 0 | S35: =SUM(S4:S34) -> 0 | ... V35: =SUM(V4:V34) -> 0
A38: 임대보증금 | B38: 3억6천
A39: 임대료율 | B39: 0.12
C40: ~27.11.30 | D40: 27.12.01~30.11.30 | E40: 30.12.1~33.11.20
A41: 수수료율 | B41: 0.12 | C41: 최저 | D41: 최저 | E41: 최저
A42: 임대료 | B42: =ROUND(B44/1.1,0) -> 0 | C42: 60000000 | D42: 63000000 | E42: 66150000
A43: VAT | B43: =+B44-B42 -> 0 | C43: =C42/10 -> 6000000 | D43: =D42/10 -> 6300000 | E43: =E42/10 -> 6615000
A44: 합계 | B44: =+[1]다복2!B35*B41 -> 0 | C44: =C43+C42 -> 66000000 | D44: =D43+D42 -> 69300000 | E44: =E43+E42 -> 72765000
E46: 임대을매출 | F46: 0 | G46: 임대을매출원가 | H46: =F48 -> -60000000
A47: 매출원가 | B47: =[1]다복2!B35-B42 -> 0
A48: 할인 | B48: =[1]다복2!C35 -> 0 | E48: 임대을매출원가 | F48: -60000000 | G48: 임대을매출_할인 | H48: 0
A49: 미지급금 | B49: =[1]다복2!D35-B44 -> 0 | E49: 미수금 | F49: 66000000 | G49: 임대을매출_수수료 | H49: 60000000
G50: 예수부가세 | H50: 6000000
F55: =SUM(F46:F52) -> 6000000 | H55: =SUM(H46:H53) -> 6000000

Sheet 테라로사
B1: ㈜학산 | C1: 테라로사 | D1: 226-81-28273 | E1: 028273
M2: 1048656659 | N2: 119948 | O2: 033138 | P2: 007072 | Q2: 037726 | R2: 015419 | S2: 072014 | T2: 045602 | U2: 054231
A3: 일 자 | B3: 현금매출액 | C3: 전자화폐 | D3: 카드매출액 | E3: 할인액 | F3: 총매출액 | G3: 입금기한 | H3: 입금일 | I3: 입금액 | J3: 잔액 | K3: 연체일 | L3: 연체료 | M3: 하나 | N3: 위쳇페이 | O3: KB국민 | P3: NH농협 | Q3: 비씨 | R3: 현대 | S3: 신한 | T3: 삼성 | U3: 롯데 | V3: 합계
A4: 46082 | D4: =V4 -> 0 | F4: =+B4+D4+E4+C4 -> 0 | J4: =+B4-I4 -> 0 | V4: =SUM(M4:U4) -> 0
A5: 46083 | D5: =V5 -> 0 | F5: =+B5+D5+E5+C5 -> 0 | J5: =+B5-I5 -> 0 | V5: =SUM(M5:U5) -> 0
A6: 46084 | D6: =V6 -> 0 | F6: =+B6+D6+E6+C6 -> 0 | J6: =+B6-I6 -> 0 | V6: =SUM(M6:U6) -> 0
A7: 46085 | D7: =V7 -> 0 | F7: =+B7+D7+E7+C7 -> 0 | J7: =+B7-I7 -> 0 | V7: =SUM(M7:U7) -> 0
A8: 46086 | D8: =V8 -> 0 | F8: =+B8+D8+E8+C8 -> 0 | J8: =+B8-I8 -> 0 | V8: =SUM(M8:U8) -> 0
A9: 46087 | D9: =V9 -> 0 | F9: =+B9+D9+E9+C9 -> 0 | J9: =+B9-I9 -> 0 | V9: =SUM(M9:U9) -> 0
A10: 46088 | D10: =V10 -> 0 | F10: =+B10+D10+E10+C10 -> 0 | J10: =+B10-I10 -> 0 | V10: =SUM(M10:U10) -> 0
A11: 46089 | D11: =V11 -> 0 | F11: =+B11+D11+E11+C11 -> 0 | J11: =+B11-I11 -> 0 | V11: =SUM(M11:U11) -> 0
A12: 46090 | D12: =V12 -> 0 | F12: =+B12+D12+E12+C12 -> 0 | J12: =+B12-I12 -> 0 | V12: =SUM(M12:U12) -> 0
A13: 46091 | D13: =V13 -> 0 | F13: =+B13+D13+E13+C13 -> 0 | J13: =+B13-I13 -> 0 | V13: =SUM(M13:U13) -> 0
A14: 46092 | D14: =V14 -> 0 | F14: =+B14+D14+E14+C14 -> 0 | J14: =+B14-I14 -> 0 | V14: =SUM(M14:U14) -> 0
A15: 46093 | D15: =V15 -> 0 | F15: =+B15+D15+E15+C15 -> 0 | J15: =+B15-I15 -> 0 | V15: =SUM(M15:U15) -> 0
... A34: 46112 | D34: =V34 -> 0 | F34: =+B34+D34+E34+C34 -> 0 | J34: =+B34-I34 -> 0 | V34: =SUM(M34:U34) -> 0
A35: 합 계 | B35: =SUM(B4:B34) -> 0 | C35: =SUM(C4:C34) -> 0 | D35: =SUM(D4:D34) -> 0 | E35: =SUM(E4:E34) -> 0 | F35: =+B35+D35+E35 -> 0 | G35: =SUM(G4:G34) -> 0 | H35: =SUM(H4:H34) -> 0 | I35: =SUM(I4:I34) -> 0 | J35: =SUM(J4:J34) -> 0 | L35: =SUM(L4:L34) -> 0 | M35: =SUM(M4:M34) -> 0 | N35: =SUM(N4:N34) -> 0 | O35: =SUM(O4:O34) -> 0 | P35: =SUM(P4:P34) -> 0 | Q35: =SUM(Q4:Q34) -> 0 | R35: =SUM(R4:R34) -> 0 | S35: =SUM(S4:S34) -> 0 | ... V35: =SUM(V4:V34) -> 0
A38: 임대보증금 | B38: 5억
A41: 수수료율 | B41: 0.23 | C41: MRG | K41: 임대을매출 | L41: =E35 -> 0 | M41: 임대을매출원가 | N41: =B46 -> 0
A42: 임대료 | B42: =ROUND(B44/1.1,0) -> 0 | C42: 50000000 | K42: 임대을매출원가 | L42: =B46 -> 0 | M42: 임대을매출_할인 | N42: =D35 -> 0
A43: VAT | B43: =+B44-B42 -> 0 | C43: =C42/10 -> 5000000 | M43: 임대을매출_수수료 | N43: =B42 -> 0
A44: 합계 | B44: =ROUND(E35*B41,0) -> 0 | C44: =C42+C43 -> 55000000 | M44: 예수부가세 | N44: =B43 -> 0
M45: 미지급금 | N45: =B47 -> 0
A46: 매출원가 | B46: =E35-B42 -> 0 | M46: 미수금 | N46: =B48 -> 0
A47: 미지급금 | B47: =C35-B44 -> 0 | E47: 쿠폰할인금액만 | L47: =SUM(L41:L46) -> 0 | N47: =SUM(N41:N46) -> 0
A48: 미수금 | B48: =B35 -> 0 | E48: <이지포스 사이트 계정>
E49: ID : hanwhacn
E50: PW : 1234

Sheet 태극당서울역점
B1: 태극당 서울역점 | C1: 태극당서울역점 | D1: 446-85-01653 | E1: 001653
M2: 1048656659 | N2: 119948 | O2: 033138 | P2: 007072 | Q2: 037726 | R2: 015419 | S2: 072014 | T2: 045602 | U2: 054231
A3: 일 자 | B3: 현금매출액 | C3: 전자화폐 | D3: 카드매출액 | E3: 할인액 | F3: 총매출액 | G3: 입금기한 | H3: 입금일 | I3: 입금액 | J3: 잔액 | K3: 연체일 | L3: 연체료 | M3: 하나 | N3: 위쳇페이 | O3: KB국민 | P3: NH농협 | Q3: 비씨 | R3: 현대 | S3: 신한 | T3: 삼성 | U3: 롯데 | V3: 합계
A4: 46082 | D4: =V4 -> 0 | F4: =+B4+D4+E4+C4 -> 0 | J4: =+B4-I4 -> 0 | V4: =SUM(M4:U4) -> 0
A5: 46083 | D5: =V5 -> 0 | F5: =+B5+D5+E5+C5 -> 0 | J5: =+B5-I5 -> 0 | V5: =SUM(M5:U5) -> 0
A6: 46084 | D6: =V6 -> 0 | F6: =+B6+D6+E6+C6 -> 0 | J6: =+B6-I6 -> 0 | V6: =SUM(M6:U6) -> 0
A7: 46085 | D7: =V7 -> 0 | F7: =+B7+D7+E7+C7 -> 0 | J7: =+B7-I7 -> 0 | V7: =SUM(M7:U7) -> 0
A8: 46086 | D8: =V8 -> 0 | F8: =+B8+D8+E8+C8 -> 0 | J8: =+B8-I8 -> 0 | V8: =SUM(M8:U8) -> 0
A9: 46087 | D9: =V9 -> 0 | F9: =+B9+D9+E9+C9 -> 0 | J9: =+B9-I9 -> 0 | V9: =SUM(M9:U9) -> 0
A10: 46088 | D10: =V10 -> 0 | F10: =+B10+D10+E10+C10 -> 0 | J10: =+B10-I10 -> 0 | V10: =SUM(M10:U10) -> 0
A11: 46089 | D11: =V11 -> 0 | F11: =+B11+D11+E11+C11 -> 0 | J11: =+B11-I11 -> 0 | V11: =SUM(M11:U11) -> 0
A12: 46090 | D12: =V12 -> 0 | F12: =+B12+D12+E12+C12 -> 0 | J12: =+B12-I12 -> 0 | V12: =SUM(M12:U12) -> 0
A13: 46091 | D13: =V13 -> 0 | F13: =+B13+D13+E13+C13 -> 0 | J13: =+B13-I13 -> 0 | V13: =SUM(M13:U13) -> 0
A14: 46092 | D14: =V14 -> 0 | F14: =+B14+D14+E14+C14 -> 0 | J14: =+B14-I14 -> 0 | V14: =SUM(M14:U14) -> 0
A15: 46093 | D15: =V15 -> 0 | F15: =+B15+D15+E15+C15 -> 0 | J15: =+B15-I15 -> 0 | V15: =SUM(M15:U15) -> 0
... A34: 46112 | D34: =V34 -> 0 | F34: =+B34+D34+E34+C34 -> 0 | J34: =+B34-I34 -> 0 | V34: =SUM(M34:U34) -> 0
A35: 합 계 | B35: =SUM(B4:B34) -> 0 | C35: =SUM(C4:C34) -> 0 | D35: =SUM(D4:D34) -> 0 | E35: =SUM(E4:E34) -> 0 | F35: =+B35+D35+E35 -> 0 | G35: =SUM(G4:G34) -> 0 | H35: =SUM(H4:H34) -> 0 | I35: =SUM(I4:I34) -> 0 | J35: =SUM(J4:J34) -> 0 | L35: =SUM(L4:L34) -> 0 | M35: =SUM(M4:M34) -> 0 | N35: =SUM(N4:N34) -> 0 | O35: =SUM(O4:O34) -> 0 | P35: =SUM(P4:P34) -> 0 | Q35: =SUM(Q4:Q34) -> 0 | R35: =SUM(R4:R34) -> 0 | S35: =SUM(S4:S34) -> 0 | ... V35: =SUM(V4:V34) -> 0
A38: 임대보증금 | B38: 1억 | C38: 1억8천1백2십만원으로 변경(09.30에 입금예정)
B40: 25.09.10~26.09.09
A41: 수수료율 | B41: 0.19 | C41: MRG | E41: 임대을매출 | F41: =E35 -> 0 | G41: 임대을매출원가 | H41: =B46 -> #REF!
A42: 임대료 | C42: =7000000+23200000 -> 30200000 | E42: 임대을매출원가 | F42: =B46 -> #REF! | G42: 임대을매출_할인 | H42: =D35 -> 0
A43: VAT | C43: =C42/10 -> 3020000 | G43: 임대을매출_수수료 | H43: =#REF! -> #REF!
A44: 합계 | C44: =C42+C43 -> 33220000 | G44: 예수부가세 | H44: =#REF! -> #REF!
G45: 미지급금 | H45: =B47 -> #REF!
A46: 매출원가 | B46: =E35-#REF! -> #REF!
A47: 미지급금 | B47: =B35+C35-#REF! -> #REF! | F47: =SUM(F41:F46) -> #REF! | H47: =SUM(H41:H46) -> #REF!
C50: 010-9047-3787
C51: 박재연 대리님

Sheet 일상정원
B1: ㈜루미호스피탈리티 | C1: 일상정원 | D1: 205-88-03143 | E1: 103143
M2: 1048656659 | N2: 119948 | O2: 033138 | P2: 007072 | Q2: 037726 | R2: 015419 | S2: 072014 | T2: 045602 | U2: 054231
A3: 일 자 | B3: 현금매출액 | C3: 전자화폐 | D3: 카드매출액 | E3: 할인액 | F3: 총매출액 | G3: 입금기한 | H3: 입금일 | I3: 입금액 | J3: 잔액 | K3: 연체일 | L3: 연체료 | M3: 하나 | N3: 위쳇페이 | O3: KB국민 | P3: NH농협 | Q3: 비씨 | R3: 현대 | S3: 신한 | T3: 삼성 | U3: 롯데 | V3: 합계
A4: 46082 | D4: =V4 -> 0 | F4: =+B4+D4+E4+C4 -> 0 | J4: =+B4-I4 -> 0 | V4: =SUM(M4:U4) -> 0
A5: 46083 | D5: =V5 -> 0 | F5: =+B5+D5+E5+C5 -> 0 | J5: =+B5-I5 -> 0 | V5: =SUM(M5:U5) -> 0
A6: 46084 | D6: =V6 -> 0 | F6: =+B6+D6+E6+C6 -> 0 | J6: =+B6-I6 -> 0 | V6: =SUM(M6:U6) -> 0
A7: 46085 | D7: =V7 -> 0 | F7: =+B7+D7+E7+C7 -> 0 | J7: =+B7-I7 -> 0 | V7: =SUM(M7:U7) -> 0
A8: 46086 | D8: =V8 -> 0 | F8: =+B8+D8+E8+C8 -> 0 | J8: =+B8-I8 -> 0 | V8: =SUM(M8:U8) -> 0
A9: 46087 | D9: =V9 -> 0 | F9: =+B9+D9+E9+C9 -> 0 | J9: =+B9-I9 -> 0 | V9: =SUM(M9:U9) -> 0
A10: 46088 | D10: =V10 -> 0 | F10: =+B10+D10+E10+C10 -> 0 | J10: =+B10-I10 -> 0 | V10: =SUM(M10:U10) -> 0
A11: 46089 | D11: =V11 -> 0 | F11: =+B11+D11+E11+C11 -> 0 | J11: =+B11-I11 -> 0 | V11: =SUM(M11:U11) -> 0
A12: 46090 | D12: =V12 -> 0 | F12: =+B12+D12+E12+C12 -> 0 | J12: =+B12-I12 -> 0 | V12: =SUM(M12:U12) -> 0
A13: 46091 | D13: =V13 -> 0 | F13: =+B13+D13+E13+C13 -> 0 | J13: =+B13-I13 -> 0 | V13: =SUM(M13:U13) -> 0
A14: 46092 | D14: =V14 -> 0 | F14: =+B14+D14+E14+C14 -> 0 | J14: =+B14-I14 -> 0 | V14: =SUM(M14:U14) -> 0
A15: 46093 | D15: =V15 -> 0 | F15: =+B15+D15+E15+C15 -> 0 | J15: =+B15-I15 -> 0 | V15: =SUM(M15:U15) -> 0
... A34: 46112 | D34: =V34 -> 0 | F34: =+B34+D34+E34+C34 -> 0 | J34: =+B34-I34 -> 0 | V34: =SUM(M34:U34) -> 0
A35: 합 계 | B35: =SUM(B4:B34) -> 0 | C35: =SUM(C4:C34) -> 0 | D35: =SUM(D4:D34) -> 0 | E35: =SUM(E4:E34) -> 0 | F35: =+B35+D35+E35 -> 0 | G35: =SUM(G4:G34) -> 0 | H35: =SUM(H4:H34) -> 0 | I35: =SUM(I4:I34) -> 0 | J35: =SUM(J4:J34) -> 0 | L35: =SUM(L4:L34) -> 0 | M35: =SUM(M4:M34) -> 0 | N35: =SUM(N4:N34) -> 0 | O35: =SUM(O4:O34) -> 0 | P35: =SUM(P4:P34) -> 0 | Q35: =SUM(Q4:Q34) -> 0 | R35: =SUM(R4:R34) -> 0 | S35: =SUM(S4:S34) -> 0 | ... V35: =SUM(V4:V34) -> 0
A38: 임대로율 10%(카드수수료 별도)
A39: "임대인" pos 사용시 임대료율 12%(카드 수수료 포함)
A41: 수수료율 | B41: 0.12 | C41: MRG
A42: 임대료 | B42: =ROUND(B44/1.1,0) -> 0 | C42: 15000000 | F42: 임대을매출 | G42: =E35 -> 0 | H42: 임대을매출원가 | I42: =B46 -> 0
A43: VAT | B43: =+B44-B42 -> 0 | C43: =C42/10 -> 1500000 | F43: 임대을매출원가 | G43: =I42 -> 0 | H43: 임대을매출_할인 | I43: =C35 -> 0
A44: 합계 | B44: =E35*B41 -> 0 | C44: =C42+C43 -> 16500000 | H44: 임대을매출_수수료 | I44: =B42 -> 0
H45: 예수부가세 | I45: =B43 -> 0
A46: 매출원가 | B46: =E35-B42 -> 0 | H46: 미지급금 | I46: =B48 -> 0
A47: 할인 | B47: =C35 -> 0 | H47: 미수금 | I47: =B35 -> 0
A48: 미지급금 | B48: =D35-B44 -> 0 | F48: 합계 | G48: =SUM(G42:G47) -> 0 | I48: =SUM(I42:I47) -> 0

Sheet 한와담
B1: ㈜LIG홈앤밀 | C1: 한와담 | D1: 106-86-88180 | E1: 088180
M2: 1048656659 | N2: 119948 | O2: 033138 | P2: 007072 | Q2: 037726 | R2: 015419 | S2: 072014 | T2: 045602 | U2: 054231
A3: 일 자 | B3: 현금매출액 | C3: 전자화폐 | D3: 카드매출액 | E3: 할인액 | F3: 총매출액 | G3: 입금기한 | H3: 입금일 | I3: 입금액 | J3: 잔액 | K3: 연체일 | L3: 연체료 | M3: 하나 | N3: 위쳇페이 | O3: KB국민 | P3: NH농협 | Q3: 비씨 | R3: 현대 | S3: 신한 | T3: 삼성 | U3: 롯데 | V3: 합계
A4: 46082 | D4: =V4 -> 0 | F4: =+B4+D4+E4+C4 -> 0 | J4: =+B4-I4 -> 0 | V4: =SUM(M4:U4) -> 0
A5: 46083 | D5: =V5 -> 0 | F5: =+B5+D5+E5+C5 -> 0 | J5: =+B5-I5 -> 0 | V5: =SUM(M5:U5) -> 0
A6: 46084 | D6: =V6 -> 0 | F6: =+B6+D6+E6+C6 -> 0 | J6: =+B6-I6 -> 0 | V6: =SUM(M6:U6) -> 0
A7: 46085 | D7: =V7 -> 0 | F7: =+B7+D7+E7+C7 -> 0 | J7: =+B7-I7 -> 0 | V7: =SUM(M7:U7) -> 0
A8: 46086 | D8: =V8 -> 0 | F8: =+B8+D8+E8+C8 -> 0 | J8: =+B8-I8 -> 0 | V8: =SUM(M8:U8) -> 0
A9: 46087 | D9: =V9 -> 0 | F9: =+B9+D9+E9+C9 -> 0 | J9: =+B9-I9 -> 0 | V9: =SUM(M9:U9) -> 0
A10: 46088 | D10: =V10 -> 0 | F10: =+B10+D10+E10+C10 -> 0 | J10: =+B10-I10 -> 0 | V10: =SUM(M10:U10) -> 0
A11: 46089 | D11: =V11 -> 0 | F11: =+B11+D11+E11+C11 -> 0 | J11: =+B11-I11 -> 0 | V11: =SUM(M11:U11) -> 0
A12: 46090 | D12: =V12 -> 0 | F12: =+B12+D12+E12+C12 -> 0 | J12: =+B12-I12 -> 0 | V12: =SUM(M12:U12) -> 0
A13: 46091 | D13: =V13 -> 0 | F13: =+B13+D13+E13+C13 -> 0 | J13: =+B13-I13 -> 0 | V13: =SUM(M13:U13) -> 0
A14: 46092 | D14: =V14 -> 0 | F14: =+B14+D14+E14+C14 -> 0 | J14: =+B14-I14 -> 0 | V14: =SUM(M14:U14) -> 0
A15: 46093 | D15: =V15 -> 0 | F15: =+B15+D15+E15+C15 -> 0 | J15: =+B15-I15 -> 0 | V15: =SUM(M15:U15) -> 0
... A34: 46112 | D34: =V34 -> 0 | F34: =+B34+D34+E34+C34 -> 0 | J34: =+B34-I34 -> 0 | V34: =SUM(M34:U34) -> 0
A35: 합 계 | B35: =SUM(B4:B34) -> 0 | C35: =SUM(C4:C34) -> 0 | D35: =SUM(D4:D34) -> 0 | E35: =SUM(E4:E34) -> 0 | F35: =+B35+D35+E35 -> 0 | G35: =SUM(G4:G34) -> 0 | H35: =SUM(H4:H34) -> 0 | I35: =SUM(I4:I34) -> 0 | J35: =SUM(J4:J34) -> 0 | L35: =SUM(L4:L34) -> 0 | M35: =SUM(M4:M34) -> 0 | N35: =SUM(N4:N34) -> 0 | O35: =SUM(O4:O34) -> 0 | P35: =SUM(P4:P34) -> 0 | Q35: =SUM(Q4:Q34) -> 0 | R35: =SUM(R4:R34) -> 0 | S35: =SUM(S4:S34) -> 0 | ... V35: =SUM(V4:V34) -> 0
A38: 010-3052-2910 | C38: 한와담 점장님 증빙
A39: 임대보증금 | B39: 1억
A40: 임대료율 | B40: 0.12 | C40: 2025년부터 적용
B41: 0.14 | C41: 포스도입
A43: 수수료율 | B43: 0.14 | C43: 최저 | E43: 임대을매출 | G43: =E35 -> 0 | H43: 임대을매출원가 | I43: =B49 -> 0
A44: 임대료 | B44: =ROUND(B46/1.1,0) -> 0 | C44: 없음 | E44: 임대을매출원가 | G44: =I43 -> 0 | H44: 임대을매출_할인 | I44: =B50 -> 0
A45: VAT | B45: =+B46-B44 -> 0 | H45: 임대을매출_수수료 | I45: =B44 -> 0
A46: 합계 | B46: =E35*B43 -> 0 | H46: 예수부가세 | I46: =B45 -> 0
H47: 미지급금 | I47: =B51 -> 0
H48: 미수금 | I48: =B35 -> 0
A49: 매출원가 | B49: =E35-B44 -> 0 | G49: =SUM(G43:G48) -> 0 | I49: =SUM(I43:I48) -> 0
A50: 할인 | B50: =D35 -> 0
A51: 미지급금 | B51: =C35-B46 -> 0
A52: 미수금 | B52: =B35 -> 0
A54: 담당자
A55: 이현지
A56: 02-3409-2946

Sheet 함루
B1: 주식회사 레버리치 파트너스 | C1: 함루 | D1: 587-86-03376 | E1: 003376
M2: 1048656659 | N2: 119948 | O2: 033138 | P2: 007072 | Q2: 037726 | R2: 015419 | S2: 072014 | T2: 045602 | U2: 054231
A3: 일 자 | B3: 현금매출액 | C3: 전자화폐 | D3: 카드매출액 | E3: 할인액 | F3: 총매출액 | G3: 입금기한 | H3: 입금일 | I3: 입금액 | J3: 잔액 | K3: 연체일 | L3: 연체료 | M3: 하나 | N3: 위쳇페이 | O3: KB국민 | P3: NH농협 | Q3: 비씨 | R3: 현대 | S3: 신한 | T3: 삼성 | U3: 롯데 | V3: 합계
A4: 46082 | D4: =V4 -> 0 | F4: =+B4+D4+E4+C4 -> 0 | J4: =+B4-I4 -> 0 | V4: =SUM(M4:U4) -> 0
A5: 46083 | D5: =V5 -> 0 | F5: =+B5+D5+E5+C5 -> 0 | J5: =+B5-I5 -> 0 | V5: =SUM(M5:U5) -> 0
A6: 46084 | D6: =V6 -> 0 | F6: =+B6+D6+E6+C6 -> 0 | J6: =+B6-I6 -> 0 | V6: =SUM(M6:U6) -> 0
A7: 46085 | D7: =V7 -> 0 | F7: =+B7+D7+E7+C7 -> 0 | J7: =+B7-I7 -> 0 | V7: =SUM(M7:U7) -> 0
A8: 46086 | D8: =V8 -> 0 | F8: =+B8+D8+E8+C8 -> 0 | J8: =+B8-I8 -> 0 | V8: =SUM(M8:U8) -> 0
A9: 46087 | D9: =V9 -> 0 | F9: =+B9+D9+E9+C9 -> 0 | J9: =+B9-I9 -> 0 | V9: =SUM(M9:U9) -> 0
A10: 46088 | D10: =V10 -> 0 | F10: =+B10+D10+E10+C10 -> 0 | J10: =+B10-I10 -> 0 | V10: =SUM(M10:U10) -> 0
A11: 46089 | D11: =V11 -> 0 | F11: =+B11+D11+E11+C11 -> 0 | J11: =+B11-I11 -> 0 | V11: =SUM(M11:U11) -> 0
A12: 46090 | D12: =V12 -> 0 | F12: =+B12+D12+E12+C12 -> 0 | J12: =+B12-I12 -> 0 | V12: =SUM(M12:U12) -> 0
A13: 46091 | D13: =V13 -> 0 | F13: =+B13+D13+E13+C13 -> 0 | J13: =+B13-I13 -> 0 | V13: =SUM(M13:U13) -> 0
A14: 46092 | D14: =V14 -> 0 | F14: =+B14+D14+E14+C14 -> 0 | J14: =+B14-I14 -> 0 | V14: =SUM(M14:U14) -> 0
A15: 46093 | D15: =V15 -> 0 | F15: =+B15+D15+E15+C15 -> 0 | J15: =+B15-I15 -> 0 | V15: =SUM(M15:U15) -> 0
... A34: 46112 | D34: =V34 -> 0 | F34: =+B34+D34+E34+C34 -> 0 | J34: =+B34-I34 -> 0 | V34: =SUM(M34:U34) -> 0
A35: 합 계 | B35: =SUM(B4:B34) -> 0 | C35: =SUM(C4:C34) -> 0 | D35: =SUM(D4:D34) -> 0 | E35: =SUM(E4:E34) -> 0 | F35: =+B35+D35+E35 -> 0 | G35: =SUM(G4:G34) -> 0 | H35: =SUM(H4:H34) -> 0 | I35: =SUM(I4:I34) -> 0 | J35: =SUM(J4:J34) -> 0 | L35: =SUM(L4:L34) -> 0 | M35: =SUM(M4:M34) -> 0 | N35: =SUM(N4:N34) -> 0 | O35: =SUM(O4:O34) -> 0 | P35: =SUM(P4:P34) -> 0 | Q35: =SUM(Q4:Q34) -> 0 | R35: =SUM(R4:R34) -> 0 | S35: =SUM(S4:S34) -> 0 | ... V35: =SUM(V4:V34) -> 0
A37: 010-2848-9189
A38: 임대보증금 | B38: 1억 | D38: 24.10월1일부터 2% 인상됨
A39: 임대료율 | B39: 1억 미만 | C39: 0.11
B40: 1억 이상 1.4억 미만 | C40: 0.12
B41: 1.4억 이상 | C41: 0.13
A44: 수수료율 | B44: 0.12 | C44: 최저
A45: 임대료 | B45: =ROUND(B47/1.1,0) -> 0 | C45: 없음 | E45: 임대을매출 | G45: =E35 -> 0 | H45: 임대을매출원가 | I45: =B50 -> 0
A46: VAT | B46: =+B47-B45 -> 0 | E46: 임대을매출원가 | G46: =B50 -> 0 | H46: 임대을매출_할인 | I46: =B51 -> 0
A47: 합계 | B47: =E35*B44 -> 0 | H47: 임대을매출_수수료 | I47: =B45 -> 0
H48: 예수부가세 | I48: =B46 -> 0
H49: 미지급금 | I49: =B53 -> 0
A50: 매출원가 | B50: =E35-B45 -> 0 | H50: 미수금 | I50: =B35 -> 0
A51: 할인 | B51: =D35 -> 0 | G51: =SUM(G45:G50) -> 0 | I51: =SUM(I45:I50) -> 0
A52: 미지급금 | B52: =C35-B47 -> 0
B53: =C35-B47 -> 0

Sheet 서울리에 포스
B1: ㈜윤월드푸드코리아 | C1: 서울리에 | D1: 427-85-01929 | E1: 001929 | AD1: 거래처코드확인
M2: 1048656659 | N2: 119948 | O2: 033138 | P2: 007072 | Q2: 037726 | R2: 015419 | S2: 072014 | T2: 045602 | U2: 054231
A3: 일 자 | B3: 현금매출액 | C3: 전자화폐 | D3: 카드매출액 | E3: 할인액 | F3: 총매출액 | G3: 입금기한 | H3: 입금일 | I3: 입금액 | J3: 잔액 | K3: 연체일 | L3: 연체료 | M3: 하나 | N3: 위쳇페이 | O3: KB국민 | P3: NH농협 | Q3: 비씨 | R3: 현대 | S3: 신한 | T3: 삼성 | U3: 롯데 | V3: 합계
A4: 46082 | D4: =V4 -> 0 | F4: =+B4+D4+E4+C4 -> 0 | J4: =+B4-I4 -> 0 | V4: =SUM(M4:U4) -> 0
A5: 46083 | D5: =V5 -> 0 | F5: =+B5+D5+E5+C5 -> 0 | J5: =+B5-I5 -> 0 | V5: =SUM(M5:U5) -> 0
A6: 46084 | D6: =V6 -> 0 | F6: =+B6+D6+E6+C6 -> 0 | J6: =+B6-I6 -> 0 | V6: =SUM(M6:U6) -> 0
A7: 46085 | D7: =V7 -> 0 | F7: =+B7+D7+E7+C7 -> 0 | J7: =+B7-I7 -> 0 | V7: =SUM(M7:U7) -> 0
A8: 46086 | D8: =V8 -> 0 | F8: =+B8+D8+E8+C8 -> 0 | J8: =+B8-I8 -> 0 | V8: =SUM(M8:U8) -> 0
A9: 46087 | D9: =V9 -> 0 | F9: =+B9+D9+E9+C9 -> 0 | J9: =+B9-I9 -> 0 | V9: =SUM(M9:U9) -> 0
A10: 46088 | D10: =V10 -> 0 | F10: =+B10+D10+E10+C10 -> 0 | J10: =+B10-I10 -> 0 | V10: =SUM(M10:U10) -> 0
A11: 46089 | D11: =V11 -> 0 | F11: =+B11+D11+E11+C11 -> 0 | J11: =+B11-I11 -> 0 | V11: =SUM(M11:U11) -> 0
A12: 46090 | D12: =V12 -> 0 | F12: =+B12+D12+E12+C12 -> 0 | J12: =+B12-I12 -> 0 | V12: =SUM(M12:U12) -> 0
A13: 46091 | D13: =V13 -> 0 | F13: =+B13+D13+E13+C13 -> 0 | J13: =+B13-I13 -> 0 | V13: =SUM(M13:U13) -> 0
A14: 46092 | D14: =V14 -> 0 | F14: =+B14+D14+E14+C14 -> 0 | J14: =+B14-I14 -> 0 | V14: =SUM(M14:U14) -> 0
A15: 46093 | D15: =V15 -> 0 | F15: =+B15+D15+E15+C15 -> 0 | J15: =+B15-I15 -> 0 | V15: =SUM(M15:U15) -> 0
... A34: 46112 | D34: =V34 -> 0 | F34: =+B34+D34+E34+C34 -> 0 | J34: =+B34-I34 -> 0 | V34: =SUM(M34:U34) -> 0
A35: 합 계 | B35: =SUM(B4:B34) -> 0 | C35: =SUM(C4:C34) -> 0 | D35: =SUM(D4:D34) -> 0 | E35: =SUM(E4:E34) -> 0 | F35: =+B35+D35+E35 -> 0 | G35: =SUM(G4:G34) -> 0 | H35: =SUM(H4:H34) -> 0 | I35: =SUM(I4:I34) -> 0 | J35: =SUM(J4:J34) -> 0 | L35: =SUM(L4:L34) -> 0 | M35: =SUM(M4:M34) -> 0 | N35: =SUM(N4:N34) -> 0 | O35: =SUM(O4:O34) -> 0 | P35: =SUM(P4:P34) -> 0 | Q35: =SUM(Q4:Q34) -> 0 | R35: =SUM(R4:R34) -> 0 | S35: =SUM(S4:S34) -> 0 | ... V35: =SUM(V4:V34) -> 0
A38: 해외카드 결제분 있을 시, BC카드 가맹점 홈페이지 확인
A40: 수수료율 | B40: 0.14 | F40: 임대을매출 | G40: =+E35 -> 0 | H40: 임대을매출원가 | I40: =+B45 -> 0
A41: 임대료 | B41: =ROUND(B43/1.1,0) -> 0 | F41: 임대을매출원가 | G41: =+I40 -> 0 | H41: 임대을매출_할인 | I41: =B46 -> 0
A42: VAT | B42: =+B43-B41 -> 0 | H42: 임대을매출_수수료 | I42: =B41 -> 0
A43: 합계 | B43: =+E35*B40 -> 0 | H43: 예수부가세 | I43: =B42 -> 0
H44: 미지급금 | I44: =+B47 -> 0
A45: 매출원가 | B45: =+E35-B41 -> 0 | H45: 미수금 | I45: =B35 -> 0
A46: 할인 | B46: =D35 -> 0 | G46: =SUM(G40:G45) -> 0 | I46: =SUM(I40:I45) -> 0
A47: 미지급금 | B47: =+C35-B43 -> 0
A49: * 당사 카드 단말기 사용 (국민 004-01-0415258 계좌)
A50: * 상품대지급일 (익월 25일까지) - 카드매출금에서 수수료 제외 후 입금 | H50: 1월부터 상품대지급 25일에
H51: ex) 12월 매출->1/10
H52: 1월 매출부터->2/25

Sheet 무원
B1: 주식회사 카페무원 | C1: 무원 | D1: 555-88-03219 | E1: 003219
M2: 1048656659 | N2: 119948 | O2: 033138 | P2: 007072 | Q2: 037726 | R2: 015419 | S2: 072014 | T2: 045602 | U2: 054231
A3: 일 자 | B3: 현금매출액 | C3: 전자화폐 | D3: 카드매출액 | E3: 할인액 | F3: 총매출액 | G3: 입금기한 | H3: 입금일 | I3: 입금액 | J3: 잔액 | K3: 연체일 | L3: 연체료 | M3: 하나 | N3: 위쳇페이 | O3: KB국민 | P3: NH농협 | Q3: 비씨 | R3: 현대 | S3: 신한 | T3: 삼성 | U3: 롯데 | V3: 합계
A4: 46082 | D4: =V4 -> 0 | F4: =+B4+D4+E4+C4 -> 0 | J4: =+B4-I4 -> 0 | V4: =SUM(M4:U4) -> 0
A5: 46083 | D5: =V5 -> 0 | F5: =+B5+D5+E5+C5 -> 0 | J5: =+B5-I5 -> 0 | V5: =SUM(M5:U5) -> 0
A6: 46084 | D6: =V6 -> 0 | F6: =+B6+D6+E6+C6 -> 0 | J6: =+B6-I6 -> 0 | V6: =SUM(M6:U6) -> 0
A7: 46085 | D7: =V7 -> 0 | F7: =+B7+D7+E7+C7 -> 0 | J7: =+B7-I7 -> 0 | V7: =SUM(M7:U7) -> 0
A8: 46086 | D8: =V8 -> 0 | F8: =+B8+D8+E8+C8 -> 0 | J8: =+B8-I8 -> 0 | V8: =SUM(M8:U8) -> 0
A9: 46087 | D9: =V9 -> 0 | F9: =+B9+D9+E9+C9 -> 0 | J9: =+B9-I9 -> 0 | V9: =SUM(M9:U9) -> 0
A10: 46088 | D10: =V10 -> 0 | F10: =+B10+D10+E10+C10 -> 0 | J10: =+B10-I10 -> 0 | V10: =SUM(M10:U10) -> 0
A11: 46089 | D11: =V11 -> 0 | F11: =+B11+D11+E11+C11 -> 0 | J11: =+B11-I11 -> 0 | V11: =SUM(M11:U11) -> 0
A12: 46090 | D12: =V12 -> 0 | F12: =+B12+D12+E12+C12 -> 0 | J12: =+B12-I12 -> 0 | V12: =SUM(M12:U12) -> 0
A13: 46091 | D13: =V13 -> 0 | F13: =+B13+D13+E13+C13 -> 0 | J13: =+B13-I13 -> 0 | V13: =SUM(M13:U13) -> 0
A14: 46092 | D14: =V14 -> 0 | F14: =+B14+D14+E14+C14 -> 0 | J14: =+B14-I14 -> 0 | V14: =SUM(M14:U14) -> 0
A15: 46093 | D15: =V15 -> 0 | F15: =+B15+D15+E15+C15 -> 0 | J15: =+B15-I15 -> 0 | V15: =SUM(M15:U15) -> 0
... A34: 46112 | D34: =V34 -> 0 | F34: =+B34+D34+E34+C34 -> 0 | J34: =+B34-I34 -> 0 | V34: =SUM(M34:U34) -> 0
A35: 합 계 | B35: =SUM(B4:B34) -> 0 | C35: =SUM(C4:C34) -> 0 | D35: =SUM(D4:D34) -> 0 | E35: =SUM(E4:E34) -> 0 | F35: =+B35+D35+E35 -> 0 | G35: =SUM(G4:G34) -> 0 | H35: =SUM(H4:H34) -> 0 | I35: =SUM(I4:I34) -> 0 | J35: =SUM(J4:J34) -> 0 | L35: =SUM(L4:L34) -> 0 | M35: =SUM(M4:M34) -> 0 | N35: =SUM(N4:N34) -> 0 | O35: =SUM(O4:O34) -> 0 | P35: =SUM(P4:P34) -> 0 | Q35: =SUM(Q4:Q34) -> 0 | R35: =SUM(R4:R34) -> 0 | S35: =SUM(S4:S34) -> 0 | ... V35: =SUM(V4:V34) -> 0
A38: 해외카드 결제분 있을 시, BC카드 가맹점 홈페이지 확인
C39: 계약 기간 1년 경과로 재설정(25.05부터 적용)
A40: 수수료율 | B40: 0.17 | C40: 최저
A41: 임대료 | B41: =ROUND(B43/1.1,0) -> 0 | C41: 8310000
A42: VAT | B42: =+B43-B41 -> 0 | C42: =C41/10 -> 831000
A43: 합계 | B43: =+E35*B40 -> 0 | C43: =C41+C42 -> 9141000
A45: 매출원가 | B45: =E35-B41 -> 0 | E45: 임대을매출 | F45: =E35 -> 0 | G45: 임대을매출원가 | H45: =B45 -> 0
A46: 할인 | B46: =D35 -> 0 | E46: 임대을매출원가 | F46: =+H45 -> 0 | G46: 임대을매출_할인 | H46: =B46 -> 0 | N46: =+H51-F51 -> 0
A47: 미지급금 | B47: =C35-B43 -> 0 | G47: 임대을매출_수수료 | H47: =+B41 -> 0
G48: 예수부가세 | H48: =+B42 -> 0
A49: * 당사 카드 단말기 사용 (국민 004-01-0415258 계좌) | G49: 미지급금 | H49: =+B47 -> 0
A50: * 상품대지급일 (익월 10일까지) - 카드매출금에서 수수료 제외 후 입금 | G50: 미수금 | H50: =+B35 -> 0
F51: =SUM(F45:F50) -> 0 | H51: =SUM(H45:H50) -> 0

Sheet 센터커피
B1: ㈜클라우드핑크 | C1: 센터커피 | D1: 742-85-01740 | E1: 055804
M2: 1048656659 | N2: 119948 | O2: 033138 | P2: 007072 | Q2: 037726 | R2: 015419 | S2: 072014 | T2: 045602 | U2: 054231
A3: 일 자 | B3: 현금매출액 | C3: 전자화폐 | D3: 카드매출액 | E3: 할인액 | F3: 총매출액 | G3: 입금기한 | H3: 입금일 | I3: 입금액 | J3: 잔액 | K3: 연체일 | L3: 연체료 | M3: 하나 | N3: 위쳇페이 | O3: KB국민 | P3: NH농협 | Q3: 비씨 | R3: 현대 | S3: 신한 | T3: 삼성 | U3: 롯데 | V3: 합계
A4: 46082 | D4: =V4 -> 0 | F4: =+B4+D4+E4+C4 -> 0 | J4: =+B4-I4 -> 0 | V4: =SUM(M4:U4) -> 0
A5: 46083 | D5: =V5 -> 0 | F5: =+B5+D5+E5+C5 -> 0 | J5: =+B5-I5 -> 0 | V5: =SUM(M5:U5) -> 0
A6: 46084 | D6: =V6 -> 0 | F6: =+B6+D6+E6+C6 -> 0 | J6: =+B6-I6 -> 0 | V6: =SUM(M6:U6) -> 0
A7: 46085 | D7: =V7 -> 0 | F7: =+B7+D7+E7+C7 -> 0 | J7: =+B7-I7 -> 0 | V7: =SUM(M7:U7) -> 0
A8: 46086 | D8: =V8 -> 0 | F8: =+B8+D8+E8+C8 -> 0 | J8: =+B8-I8 -> 0 | V8: =SUM(M8:U8) -> 0
A9: 46087 | D9: =V9 -> 0 | F9: =+B9+D9+E9+C9 -> 0 | J9: =+B9-I9 -> 0 | V9: =SUM(M9:U9) -> 0
A10: 46088 | D10: =V10 -> 0 | F10: =+B10+D10+E10+C10 -> 0 | J10: =+B10-I10 -> 0 | V10: =SUM(M10:U10) -> 0
A11: 46089 | D11: =V11 -> 0 | F11: =+B11+D11+E11+C11 -> 0 | J11: =+B11-I11 -> 0 | V11: =SUM(M11:U11) -> 0
A12: 46090 | D12: =V12 -> 0 | F12: =+B12+D12+E12+C12 -> 0 | J12: =+B12-I12 -> 0 | V12: =SUM(M12:U12) -> 0
A13: 46091 | D13: =V13 -> 0 | F13: =+B13+D13+E13+C13 -> 0 | J13: =+B13-I13 -> 0 | V13: =SUM(M13:U13) -> 0
A14: 46092 | D14: =V14 -> 0 | F14: =+B14+D14+E14+C14 -> 0 | J14: =+B14-I14 -> 0 | V14: =SUM(M14:U14) -> 0
A15: 46093 | D15: =V15 -> 0 | F15: =+B15+D15+E15+C15 -> 0 | J15: =+B15-I15 -> 0 | V15: =SUM(M15:U15) -> 0
... A34: 46112 | D34: =V34 -> 0 | F34: =+B34+D34+E34+C34 -> 0 | J34: =+B34-I34 -> 0 | V34: =SUM(M34:U34) -> 0
A35: 합 계 | B35: =SUM(B4:B34) -> 0 | C35: =SUM(C4:C34) -> 0 | D35: =SUM(D4:D34) -> 0 | E35: =SUM(E4:E34) -> 0 | F35: =+B35+D35+E35 -> 0 | G35: =SUM(G4:G34) -> 0 | H35: =SUM(H4:H34) -> 0 | I35: =SUM(I4:I34) -> 0 | J35: =SUM(J4:J34) -> 0 | L35: =SUM(L4:L34) -> 0 | M35: =SUM(M4:M34) -> 0 | N35: =SUM(N4:N34) -> 0 | O35: =SUM(O4:O34) -> 0 | P35: =SUM(P4:P34) -> 0 | Q35: =SUM(Q4:Q34) -> 0 | R35: =SUM(R4:R34) -> 0 | S35: =SUM(S4:S34) -> 0 | ... V35: =SUM(V4:V34) -> 0
A37: * 매월 정산내역 메일 전송 lyy@cloudpink.co.kr
A38: 12월부터 바뀐 사업자등록증(지점사업자)으로 매출 입력
A39: 12월 세금계산서부터 변경된 사업자번호로 발행(742-85-01740)
A41: 임대보증금 | B41: 5천만원
A42: 임대료율 | B42: 0.17
A44: 수수료율 | B44: =+B42 -> 0.17 | C44: 최저 | E44: 임대을매출 | G44: =E35 -> 0 | H44: 임대을매출원가 | I44: =G45 -> 0
A45: 임대료 | B45: =ROUND(B47/1.1,0) -> 0 | C45: 없음 | E45: 임대을매출원가 | G45: =B50 -> 0 | H45: 임대을매출_할인 | I45: =B51 -> 0
A46: VAT | B46: =+B47-B45 -> 0 | H46: 임대을매출_수수료 | I46: =B45 -> 0
A47: 합계 | B47: =E35*B44 -> 0 | H47: 예수부가세 | I47: =B46 -> 0
H48: 미지급금 | I48: =B52 -> 0
H49: 미수금 | I49: =B35 -> 0
A50: 매출원가 | B50: =E35-B45 -> 0 | G50: =G44+G45 -> 0 | I50: =SUM(I44:I49) -> 0
A51: 할인 | B51: =D35 -> 0
A52: 미지급금 | B52: =C35-B47 -> 0

Sheet 아트태그(팝업)
B1: 주식회사 아트태그 | C1: 아트태그 | D1: 784-88-03118 | E1: 003118
M2: 1048656659 | N2: 119948 | O2: 033138 | P2: 007072 | Q2: 037726 | R2: 015419 | S2: 072014 | T2: 045602 | U2: 054231
A3: 일 자 | B3: 현금매출액 | C3: 전자화폐 | D3: 카드매출액 | E3: 할인액 | F3: 총매출액 | G3: 입금기한 | H3: 입금일 | I3: 입금액 | J3: 잔액 | K3: 연체일 | L3: 연체료 | M3: 하나 | N3: 위쳇페이 | O3: KB국민 | P3: NH농협 | Q3: 비씨 | R3: 현대 | S3: 신한 | T3: 삼성 | U3: 롯데 | V3: 합계
A4: 46082 | D4: =V4 -> 0 | F4: =+B4+D4+E4+C4 -> 0 | J4: =+B4-I4 -> 0 | V4: =SUM(M4:U4) -> 0
A5: 46083 | D5: =V5 -> 0 | F5: =+B5+D5+E5+C5 -> 0 | J5: =+B5-I5 -> 0 | V5: =SUM(M5:U5) -> 0
A6: 46084 | D6: =V6 -> 0 | F6: =+B6+D6+E6+C6 -> 0 | J6: =+B6-I6 -> 0 | V6: =SUM(M6:U6) -> 0
A7: 46085 | D7: =V7 -> 0 | F7: =+B7+D7+E7+C7 -> 0 | J7: =+B7-I7 -> 0 | V7: =SUM(M7:U7) -> 0
A8: 46086 | D8: =V8 -> 0 | F8: =+B8+D8+E8+C8 -> 0 | J8: =+B8-I8 -> 0 | V8: =SUM(M8:U8) -> 0
A9: 46087 | D9: =V9 -> 0 | F9: =+B9+D9+E9+C9 -> 0 | J9: =+B9-I9 -> 0 | V9: =SUM(M9:U9) -> 0
A10: 46088 | D10: =V10 -> 0 | F10: =+B10+D10+E10+C10 -> 0 | J10: =+B10-I10 -> 0 | V10: =SUM(M10:U10) -> 0
A11: 46089 | D11: =V11 -> 0 | F11: =+B11+D11+E11+C11 -> 0 | J11: =+B11-I11 -> 0 | V11: =SUM(M11:U11) -> 0
A12: 46090 | D12: =V12 -> 0 | F12: =+B12+D12+E12+C12 -> 0 | J12: =+B12-I12 -> 0 | V12: =SUM(M12:U12) -> 0
A13: 46091 | D13: =V13 -> 0 | F13: =+B13+D13+E13+C13 -> 0 | J13: =+B13-I13 -> 0 | V13: =SUM(M13:U13) -> 0
A14: 46092 | D14: =V14 -> 0 | F14: =+B14+D14+E14+C14 -> 0 | J14: =+B14-I14 -> 0 | V14: =SUM(M14:U14) -> 0
A15: 46093 | D15: =V15 -> 0 | F15: =+B15+D15+E15+C15 -> 0 | J15: =+B15-I15 -> 0 | V15: =SUM(M15:U15) -> 0
... A34: 46112 | D34: =V34 -> 0 | F34: =+B34+D34+E34+C34 -> 0 | J34: =+B34-I34 -> 0 | V34: =SUM(M34:U34) -> 0
A35: 합 계 | B35: =SUM(B4:B34) -> 0 | C35: =SUM(C4:C34) -> 0 | D35: =SUM(D4:D34) -> 0 | E35: =SUM(E4:E34) -> 0 | F35: =+B35+D35+E35 -> 0 | G35: =SUM(G4:G34) -> 0 | H35: =SUM(H4:H34) -> 0 | I35: =SUM(I4:I34) -> 0 | J35: =SUM(J4:J34) -> 0 | L35: =SUM(L4:L34) -> 0 | M35: =SUM(M4:M34) -> 0 | N35: =SUM(N4:N34) -> 0 | O35: =SUM(O4:O34) -> 0 | P35: =SUM(P4:P34) -> 0 | Q35: =SUM(Q4:Q34) -> 0 | R35: =SUM(R4:R34) -> 0 | S35: =SUM(S4:S34) -> 0 | ... V35: =SUM(V4:V34) -> 0
A38: 에디션,굿즈 10%
A39: 원화 15%
A40: 에디션 | B40: 10000 | C40: 이지포스 아트태그 계정 로그인 | K40: 임대을매출 | L40: =F35 -> 0 | M40: 임대을매출원가 | N40: =L41 -> -1047381.8
A41: 굿즈 | B41: 3696200 | C41: ID:hanwhas023, PW: 12345 | F41: 조회해서 분류별 금액 넣기 | K41: 임대을매출원가 | L41: =L48 -> -1047381.8 | M41: 임대을매출_할인 | N41: =C35 -> 0
A42: 원화 | B42: 5210000 | M42: 임대을매출_수수료 | N42: =+B45+D45+F45 -> 1047381.8
B43: 에디션 | D43: 굿즈 | F43: 원화 | M43: 예수부가세 | N43: =B46+D46+F46 -> 104738.18
A44: 수수료율 | B44: 0.1 | C44: 수수료율 | D44: 0.1 | E44: 수수료율 | F44: 0.15 | M44: 미지급금 | N44: =L49 -> -1152120
A45: 임대료 | B45: =+B47/1.1 -> 909.09091 | C45: 임대료 | D45: =+D47/1.1 -> 336018.18 | E45: 임대료 | F45: =+F47/1.1 -> 710454.55 | M45: 미수금 | N45: =L50 -> 0
A46: VAT | B46: =+B47-B45 -> 90.909091 | C46: VAT | D46: =+D47-D45 -> 33601.818 | E46: VAT | F46: =+F47-F45 -> 71045.455 | L46: =SUM(L40:L45) -> -1047381.8 | N46: =SUM(N40:N45) -> -1047381.8
A47: 합계 | B47: =+B40*B44 -> 1000 | C47: 합계 | D47: =+B41*D44 -> 369620 | E47: 합계 | F47: =+B42*F44 -> 781500
A48: * 당사 카드 단말기 사용 (134-05-063053 계좌) | K48: 매출원가 | L48: =F35-B45-D45-F45 -> -1047381.8
K49: 미지급금 | L49: =D35-B47-D47-F47 -> -1152120
K50: 미수금 | L50: =B35 -> 0
A51: * 상품대지급일 (익월 10일까지) - 카드매출금에서 수수료 제외 후 입금

Sheet 돈이찌
B1: 돈이찌서울역점 | C1: 돈이찌 | D1: 803-81-02013 | E1: 002013
K2: 현금입금 | M2: 1048656659 | N2: 119948 | O2: 033138 | P2: 007072 | Q2: 037726 | R2: 015419 | S2: 072014 | T2: 045602 | U2: 054231
A3: 일 자 | B3: 현금매출액 | C3: 전자화폐 | D3: 카드매출액 | E3: 할인액 | F3: 총매출액 | G3: 입금기한 | H3: 입금일 | I3: 입금액 | J3: 잔액 | K3: 연체일 | L3: 연체료 | M3: 하나 | N3: 위쳇페이 | O3: KB국민 | P3: NH농협 | Q3: 비씨 | R3: 현대 | S3: 신한 | T3: 삼성 | U3: 롯데 | V3: 합계
A4: 46082 | D4: =V4 -> 0 | F4: =+B4+D4+E4+C4 -> 0 | J4: =+B4-I4 -> 0 | V4: =SUM(M4:U4) -> 0
A5: 46083 | D5: =V5 -> 0 | F5: =+B5+D5+E5+C5 -> 0 | J5: =+B5-I5 -> 0 | V5: =SUM(M5:U5) -> 0
A6: 46084 | D6: =V6 -> 0 | F6: =+B6+D6+E6+C6 -> 0 | J6: =+B6-I6 -> 0 | V6: =SUM(M6:U6) -> 0
A7: 46085 | D7: =V7 -> 0 | F7: =+B7+D7+E7+C7 -> 0 | J7: =+B7-I7 -> 0 | V7: =SUM(M7:U7) -> 0
A8: 46086 | D8: =V8 -> 0 | F8: =+B8+D8+E8+C8 -> 0 | J8: =+B8-I8 -> 0 | V8: =SUM(M8:U8) -> 0
A9: 46087 | D9: =V9 -> 0 | F9: =+B9+D9+E9+C9 -> 0 | J9: =+B9-I9 -> 0 | V9: =SUM(M9:U9) -> 0
A10: 46088 | D10: =V10 -> 0 | F10: =+B10+D10+E10+C10 -> 0 | J10: =+B10-I10 -> 0 | V10: =SUM(M10:U10) -> 0
A11: 46089 | D11: =V11 -> 0 | F11: =+B11+D11+E11+C11 -> 0 | J11: =+B11-I11 -> 0 | V11: =SUM(M11:U11) -> 0
A12: 46090 | D12: =V12 -> 0 | F12: =+B12+D12+E12+C12 -> 0 | J12: =+B12-I12 -> 0 | V12: =SUM(M12:U12) -> 0
A13: 46091 | D13: =V13 -> 0 | F13: =+B13+D13+E13+C13 -> 0 | J13: =+B13-I13 -> 0 | V13: =SUM(M13:U13) -> 0
A14: 46092 | D14: =V14 -> 0 | F14: =+B14+D14+E14+C14 -> 0 | J14: =+B14-I14 -> 0 | V14: =SUM(M14:U14) -> 0
A15: 46093 | D15: =V15 -> 0 | F15: =+B15+D15+E15+C15 -> 0 | J15: =+B15-I15 -> 0 | V15: =SUM(M15:U15) -> 0
... A34: 46112 | D34: =V34 -> 0 | F34: =+B34+D34+E34+C34 -> 0 | J34: =+B34-I34 -> 0 | V34: =SUM(M34:U34) -> 0
A35: 합 계 | B35: =SUM(B4:B34) -> 0 | C35: =SUM(C4:C34) -> 0 | D35: =SUM(D4:D34) -> 0 | E35: =SUM(E4:E34) -> 0 | F35: =+B35+D35+E35 -> 0 | G35: =SUM(G4:G34) -> 0 | H35: =SUM(H4:H34) -> 0 | I35: =SUM(I4:I34) -> 0 | J35: =SUM(J4:J34) -> 0 | L35: =SUM(L4:L34) -> 0 | M35: =SUM(M4:M34) -> 0 | N35: =SUM(N4:N34) -> 0 | O35: =SUM(O4:O34) -> 0 | P35: =SUM(P4:P34) -> 0 | Q35: =SUM(Q4:Q34) -> 0 | R35: =SUM(R4:R34) -> 0 | S35: =SUM(S4:S34) -> 0 | ... V35: =SUM(V4:V34) -> 0
A38: 해외카드 결제분 있을 시, BC카드 가맹점 홈페이지 확인
A40: 수수료율 | B40: 0.2 | E40: 최저 | N40: 임대을매출 | O40: =H35 -> 0 | P40: 임대을매출원가 | Q40: =O41 -> 0
A41: 임대료 | B41: =ROUND(B43/1.1,0) -> 0 | E41: 12000000 | N41: 임대을매출원가 | O41: =B45 -> 0 | P41: 임대을매출_할인 | Q41: =G35 -> 0
A42: VAT | B42: =+B43-B41 -> 0 | E42: 1200000 | P42: 임대을매출_수수료 | Q42: =B41 -> 0
A43: 합계 | B43: =+H35*B40 -> 0 | E43: =E41+E42 -> 13200000 | J43: =H35-G35 -> 0 | P43: 예수부가세 | Q43: =B42 -> 0
P44: 미지급금 | Q44: =B47 -> 0
A45: 매출원가 | B45: =H35-B41 -> 0
A46: 할인 | B46: =G35 -> 0 | O46: =SUM(O40:O45) -> 0 | Q46: =SUM(Q40:Q45) -> 0
A47: 미지급금 | B47: =F35+E35+B35-B43 -> 0
A49: * 당사 카드 단말기 사용 (국민 004-01-0415258 계좌)
A50: * 상품대지급일 (익월 10일까지) - 카드매출금에서 수수료 제외 후 입금

Sheet 중화가정
B1: 중화가정 서울역점 | C1: 중화가정 | D1: 146-85-02771 | E1: 002771
M2: 1048656659 | N2: 119948 | O2: 033138 | P2: 007072 | Q2: 037726 | R2: 015419 | S2: 072014 | T2: 045602 | U2: 054231
A3: 일 자 | B3: 현금매출액 | C3: 전자화폐 | D3: 카드매출액 | E3: 할인액 | F3: 총매출액 | G3: 입금기한 | H3: 입금일 | I3: 입금액 | J3: 잔액 | K3: 연체일 | L3: 연체료 | M3: 하나 | N3: 위쳇페이 | O3: KB국민 | P3: NH농협 | Q3: 비씨 | R3: 현대 | S3: 신한 | T3: 삼성 | U3: 롯데 | V3: 합계
A4: 46082 | D4: =V4 -> 0 | F4: =+B4+D4+E4+C4 -> 0 | J4: =+B4-I4 -> 0 | V4: =SUM(M4:U4) -> 0
A5: 46083 | D5: =V5 -> 0 | F5: =+B5+D5+E5+C5 -> 0 | J5: =+B5-I5 -> 0 | V5: =SUM(M5:U5) -> 0
A6: 46084 | D6: =V6 -> 0 | F6: =+B6+D6+E6+C6 -> 0 | J6: =+B6-I6 -> 0 | V6: =SUM(M6:U6) -> 0
A7: 46085 | D7: =V7 -> 0 | F7: =+B7+D7+E7+C7 -> 0 | J7: =+B7-I7 -> 0 | V7: =SUM(M7:U7) -> 0
A8: 46086 | D8: =V8 -> 0 | F8: =+B8+D8+E8+C8 -> 0 | J8: =+B8-I8 -> 0 | V8: =SUM(M8:U8) -> 0
A9: 46087 | D9: =V9 -> 0 | F9: =+B9+D9+E9+C9 -> 0 | J9: =+B9-I9 -> 0 | V9: =SUM(M9:U9) -> 0
A10: 46088 | D10: =V10 -> 0 | F10: =+B10+D10+E10+C10 -> 0 | J10: =+B10-I10 -> 0 | V10: =SUM(M10:U10) -> 0
A11: 46089 | D11: =V11 -> 0 | F11: =+B11+D11+E11+C11 -> 0 | J11: =+B11-I11 -> 0 | V11: =SUM(M11:U11) -> 0
A12: 46090 | D12: =V12 -> 0 | F12: =+B12+D12+E12+C12 -> 0 | J12: =+B12-I12 -> 0 | V12: =SUM(M12:U12) -> 0
A13: 46091 | D13: =V13 -> 0 | F13: =+B13+D13+E13+C13 -> 0 | J13: =+B13-I13 -> 0 | V13: =SUM(M13:U13) -> 0
A14: 46092 | D14: =V14 -> 0 | F14: =+B14+D14+E14+C14 -> 0 | J14: =+B14-I14 -> 0 | V14: =SUM(M14:U14) -> 0
A15: 46093 | D15: =V15 -> 0 | F15: =+B15+D15+E15+C15 -> 0 | J15: =+B15-I15 -> 0 | V15: =SUM(M15:U15) -> 0
... A34: 46112 | D34: =V34 -> 0 | F34: =+B34+D34+E34+C34 -> 0 | J34: =+B34-I34 -> 0 | V34: =SUM(M34:U34) -> 0
A35: 합 계 | B35: =SUM(B4:B34) -> 0 | C35: =SUM(C4:C34) -> 0 | D35: =SUM(D4:D34) -> 0 | E35: =SUM(E4:E34) -> 0 | F35: =+B35+D35+E35 -> 0 | G35: =SUM(G4:G34) -> 0 | H35: =SUM(H4:H34) -> 0 | I35: =SUM(I4:I34) -> 0 | J35: =SUM(J4:J34) -> 0 | L35: =SUM(L4:L34) -> 0 | M35: =SUM(M4:M34) -> 0 | N35: =SUM(N4:N34) -> 0 | O35: =SUM(O4:O34) -> 0 | P35: =SUM(P4:P34) -> 0 | Q35: =SUM(Q4:Q34) -> 0 | R35: =SUM(R4:R34) -> 0 | S35: =SUM(S4:S34) -> 0 | ... V35: =SUM(V4:V34) -> 0
Z37: 27017000
A38: 해외카드 결제분 있을 시, BC카드 가맹점 홈페이지 확인
A40: 수수료율 | B40: 0.2 | E40: 최저 | G40: 임대을매출 | H40: =+H35 -> 0 | I40: 임대을매출원가 | J40: =+B45 -> 0 | Z40: 최저
A41: 임대료 | B41: =ROUND(B43/1.1,0) -> 0 | E41: 13000000 | G41: 임대을매출원가 | H41: =+J40 -> 0 | I41: 임대을매출_할인 | J41: =B46 -> 0 | Z41: 13000000
A42: VAT | B42: =+B43-B41 -> 0 | E42: 1300000 | I42: 임대을매출_수수료 | J42: =+B41 -> 0 | Z42: 1300000
A43: 합계 | B43: =+H35*B40 -> 0 | E43: =E41+E42 -> 14300000 | I43: 예수부가세 | J43: =+B42 -> 0 | Z43: =Z41+Z42 -> 14300000
I44: 미지급금 | J44: =+B47 -> 0
A45: 매출원가 | B45: =H35-B41 -> 0
A46: 할인 | B46: =G35 -> 0 | H46: =SUM(H40:H45) -> 0 | J46: =SUM(J40:J45) -> 0
A47: 미지급금 | B47: =F35+E35+B35-B43 -> 0 | E47: =H35-G35-B43 -> 0
A49: * 당사 카드 단말기 사용 (국민 004-01-0415258 계좌)
A50: * 상품대지급일 (익월 10일까지) - 카드매출금에서 수수료 제외 후 입금

Sheet 가족회관
B1: 가족회관 서울역점 | C1: 가족회관 | D1: 768-85-02396 | E1: 002396
M2: 1048656659 | N2: 119948 | O2: 033138 | P2: 007072 | Q2: 037726 | R2: 015419 | S2: 072014 | T2: 045602 | U2: 054231
A3: 일 자 | B3: 현금매출액 | C3: 전자화폐 | D3: 카드매출액 | E3: 할인액 | F3: 총매출액 | G3: 입금기한 | H3: 입금일 | I3: 입금액 | J3: 잔액 | K3: 연체일 | L3: 연체료 | M3: 하나 | N3: 위쳇페이 | O3: KB국민 | P3: NH농협 | Q3: 비씨 | R3: 현대 | S3: 신한 | T3: 삼성 | U3: 롯데 | V3: 합계
A4: 46082 | D4: =V4 -> 0 | F4: =+B4+D4+E4+C4 -> 0 | J4: =+B4-I4 -> 0 | V4: =SUM(M4:U4) -> 0
A5: 46083 | D5: =V5 -> 0 | F5: =+B5+D5+E5+C5 -> 0 | J5: =+B5-I5 -> 0 | V5: =SUM(M5:U5) -> 0
A6: 46084 | D6: =V6 -> 0 | F6: =+B6+D6+E6+C6 -> 0 | J6: =+B6-I6 -> 0 | V6: =SUM(M6:U6) -> 0
A7: 46085 | D7: =V7 -> 0 | F7: =+B7+D7+E7+C7 -> 0 | J7: =+B7-I7 -> 0 | V7: =SUM(M7:U7) -> 0
A8: 46086 | D8: =V8 -> 0 | F8: =+B8+D8+E8+C8 -> 0 | J8: =+B8-I8 -> 0 | V8: =SUM(M8:U8) -> 0
A9: 46087 | D9: =V9 -> 0 | F9: =+B9+D9+E9+C9 -> 0 | J9: =+B9-I9 -> 0 | V9: =SUM(M9:U9) -> 0
A10: 46088 | D10: =V10 -> 0 | F10: =+B10+D10+E10+C10 -> 0 | J10: =+B10-I10 -> 0 | V10: =SUM(M10:U10) -> 0
A11: 46089 | D11: =V11 -> 0 | F11: =+B11+D11+E11+C11 -> 0 | J11: =+B11-I11 -> 0 | V11: =SUM(M11:U11) -> 0
A12: 46090 | D12: =V12 -> 0 | F12: =+B12+D12+E12+C12 -> 0 | J12: =+B12-I12 -> 0 | V12: =SUM(M12:U12) -> 0
A13: 46091 | D13: =V13 -> 0 | F13: =+B13+D13+E13+C13 -> 0 | J13: =+B13-I13 -> 0 | V13: =SUM(M13:U13) -> 0
A14: 46092 | D14: =V14 -> 0 | F14: =+B14+D14+E14+C14 -> 0 | J14: =+B14-I14 -> 0 | V14: =SUM(M14:U14) -> 0
A15: 46093 | D15: =V15 -> 0 | F15: =+B15+D15+E15+C15 -> 0 | J15: =+B15-I15 -> 0 | V15: =SUM(M15:U15) -> 0
... A34: 46112 | D34: =V34 -> 0 | F34: =+B34+D34+E34+C34 -> 0 | J34: =+B34-I34 -> 0 | V34: =SUM(M34:U34) -> 0
A35: 합 계 | B35: =SUM(B4:B34) -> 0 | C35: =SUM(C4:C34) -> 0 | D35: =SUM(D4:D34) -> 0 | E35: =SUM(E4:E34) -> 0 | F35: =+B35+D35+E35 -> 0 | G35: =SUM(G4:G34) -> 0 | H35: =SUM(H4:H34) -> 0 | I35: =SUM(I4:I34) -> 0 | J35: =SUM(J4:J34) -> 0 | L35: =SUM(L4:L34) -> 0 | M35: =SUM(M4:M34) -> 0 | N35: =SUM(N4:N34) -> 0 | O35: =SUM(O4:O34) -> 0 | P35: =SUM(P4:P34) -> 0 | Q35: =SUM(Q4:Q34) -> 0 | R35: =SUM(R4:R34) -> 0 | S35: =SUM(S4:S34) -> 0 | ... V35: =SUM(V4:V34) -> 0
A38: 해외카드 결제분 있을 시, BC카드 가맹점 홈페이지 확인
A40: 수수료율 | B40: 0.2 | E40: 최저 | G40: 임대을매출 | H40: =+H35 -> 0 | I40: 임대을매출원가 | J40: =+B45 -> 0
A41: 임대료 | B41: =ROUND(B43/1.1,0) -> 0 | E41: 13000000 | G41: 임대을매출원가 | H41: =+J40 -> 0 | I41: 임대을매출_할인 | J41: =B46 -> 0
A42: VAT | B42: =+B43-B41 -> 0 | E42: 1300000 | I42: 임대을매출_수수료 | J42: =+B41 -> 0
A43: 합계 | B43: =+H35*B40 -> 0 | E43: =E41+E42 -> 14300000 | I43: 예수부가세 | J43: =+B42 -> 0
I44: 미지급금 | J44: =+B47 -> 0
A45: 매출원가 | B45: =H35-B41 -> 0 | L45: =SUM(L39:L44) -> 0 | N45: =SUM(N39:N44) -> 0
A46: 할인 | B46: =G35 -> 0
A47: 미지급금 | B47: =F35+B35+E35-B43 -> 0 | E47: =H35-G35-B43 -> 0
A49: * 당사 카드 단말기 사용 (국민 004-01-0415258 계좌)
A50: * 상품대지급일 (익월 10일까지) - 카드매출금에서 수수료 제외 후 입금
A51: jm_park0707@naver.com으로 매출 메일 전송하기
J57: =E38+F38 -> 0

Sheet 땀땀
B1: 땀땀 서울역점 | C1: 땀땀 | D1: 199-88-02742 | E1: 002742
M2: 1048656659 | N2: 119948 | O2: 033138 | P2: 007072 | Q2: 037726 | R2: 015419 | S2: 072014 | T2: 045602 | U2: 054231
A3: 일 자 | B3: 현금매출액 | C3: 전자화폐 | D3: 카드매출액 | E3: 할인액 | F3: 총매출액 | G3: 입금기한 | H3: 입금일 | I3: 입금액 | J3: 잔액 | K3: 연체일 | L3: 연체료 | M3: 하나 | N3: 위쳇페이 | O3: KB국민 | P3: NH농협 | Q3: 비씨 | R3: 현대 | S3: 신한 | T3: 삼성 | U3: 롯데 | V3: 합계
A4: 46082 | D4: =V4 -> 0 | F4: =+B4+D4+E4+C4 -> 0 | J4: =+B4-I4 -> 0 | V4: =SUM(M4:U4) -> 0
A5: 46083 | D5: =V5 -> 0 | F5: =+B5+D5+E5+C5 -> 0 | J5: =+B5-I5 -> 0 | V5: =SUM(M5:U5) -> 0
A6: 46084 | D6: =V6 -> 0 | F6: =+B6+D6+E6+C6 -> 0 | J6: =+B6-I6 -> 0 | V6: =SUM(M6:U6) -> 0
A7: 46085 | D7: =V7 -> 0 | F7: =+B7+D7+E7+C7 -> 0 | J7: =+B7-I7 -> 0 | V7: =SUM(M7:U7) -> 0
A8: 46086 | D8: =V8 -> 0 | F8: =+B8+D8+E8+C8 -> 0 | J8: =+B8-I8 -> 0 | V8: =SUM(M8:U8) -> 0
A9: 46087 | D9: =V9 -> 0 | F9: =+B9+D9+E9+C9 -> 0 | J9: =+B9-I9 -> 0 | V9: =SUM(M9:U9) -> 0
A10: 46088 | D10: =V10 -> 0 | F10: =+B10+D10+E10+C10 -> 0 | J10: =+B10-I10 -> 0 | V10: =SUM(M10:U10) -> 0
A11: 46089 | D11: =V11 -> 0 | F11: =+B11+D11+E11+C11 -> 0 | J11: =+B11-I11 -> 0 | V11: =SUM(M11:U11) -> 0
A12: 46090 | D12: =V12 -> 0 | F12: =+B12+D12+E12+C12 -> 0 | J12: =+B12-I12 -> 0 | V12: =SUM(M12:U12) -> 0
A13: 46091 | D13: =V13 -> 0 | F13: =+B13+D13+E13+C13 -> 0 | J13: =+B13-I13 -> 0 | V13: =SUM(M13:U13) -> 0
A14: 46092 | D14: =V14 -> 0 | F14: =+B14+D14+E14+C14 -> 0 | J14: =+B14-I14 -> 0 | V14: =SUM(M14:U14) -> 0
A15: 46093 | D15: =V15 -> 0 | F15: =+B15+D15+E15+C15 -> 0 | J15: =+B15-I15 -> 0 | V15: =SUM(M15:U15) -> 0
... A34: 46112 | D34: =V34 -> 0 | F34: =+B34+D34+E34+C34 -> 0 | J34: =+B34-I34 -> 0 | V34: =SUM(M34:U34) -> 0
A35: 합 계 | B35: =SUM(B4:B34) -> 0 | C35: =SUM(C4:C34) -> 0 | D35: =SUM(D4:D34) -> 0 | E35: =SUM(E4:E34) -> 0 | F35: =+B35+D35+E35 -> 0 | G35: =SUM(G4:G34) -> 0 | H35: =SUM(H4:H34) -> 0 | I35: =SUM(I4:I34) -> 0 | J35: =SUM(J4:J34) -> 0 | L35: =SUM(L4:L34) -> 0 | M35: =SUM(M4:M34) -> 0 | N35: =SUM(N4:N34) -> 0 | O35: =SUM(O4:O34) -> 0 | P35: =SUM(P4:P34) -> 0 | Q35: =SUM(Q4:Q34) -> 0 | R35: =SUM(R4:R34) -> 0 | S35: =SUM(S4:S34) -> 0 | ... V35: =SUM(V4:V34) -> 0
H37: =F35-E35 -> 0
A38: 해외카드 결제분 있을 시, BC카드 가맹점 홈페이지 확인
A39: '땀땀' : 매출 1.6억 이상 시, 초과분에 한정하여 12.0% / 보증금 1.6억원 100% 보증보험증권 대체
A40: 수수료율 | B40: 0.14 | C40: 0.12 | E40: =F35/1.1 -> 0 | F40: 최저
A41: 임대료 | B41: =E41*B40 -> 22400000 | C41: =E42*C40 -> -19200000 | D41: 매출 | E41: 160000000 | F41: 16000000
A42: VAT | B42: =B41*0.1 -> 2240000 | C42: =C41*0.1 -> -1920000 | D42: 초과분 | E42: =E40-E41 -> -160000000 | F42: 1600000
A43: 합계 | B43: =B41+B42 -> 24640000 | C43: =C41+C42 -> -21120000 | F43: =F41+F42 -> 17600000
A45: 매출원가 | B45: =F35-(B41+C41) -> -3200000 | D45: 010-6321-3741 | E45: 해안 세무법인 연락처
A46: 할인 | B46: =E35 -> 0
A47: 미지급금 | B47: =D35+B35+C35-(B43+C43)+J40 -> -3520000 | D47: =F35-E35-B43-C43 -> -3520000
F48: 임대을매출 | G48: =+F35 -> 0 | H48: 임대을매출원가 | I48: =+B45 -> -3200000
A49: * 당사 카드 단말기 사용 (국민 004-01-0415258 계좌) | F49: 임대을매출원가 | G49: =+I48 -> -3200000 | H49: 임대을매출_할인 | I49: =B46 -> 0
A50: * 상품대지급일 (익월 10일까지) - 카드매출금에서 수수료 제외 후 입금 | H50: 임대을매출_수수료 | I50: =+B41+C41 -> 3200000
H51: 예수부가세 | I51: =+B42+C42 -> 320000
H52: 미지급금 | I52: =+B47 -> -3520000
G54: =SUM(G48:G53) -> -3200000 | I54: =SUM(I48:I53) -> -3200000

Sheet 오장동흥남집
B1: 오장동흥남집 서울역점 | C1: 오장동흥남집 | D1: 339-48-01141 | E1: 001141
M2: 1048656659 | N2: 119948 | O2: 033138 | P2: 007072 | Q2: 037726 | R2: 015419 | S2: 072014 | T2: 045602 | U2: 054231
A3: 일 자 | B3: 현금매출액 | C3: 전자화폐 | D3: 카드매출액 | E3: 할인액 | F3: 총매출액 | G3: 입금기한 | H3: 입금일 | I3: 입금액 | J3: 잔액 | K3: 연체일 | L3: 연체료 | M3: 하나 | N3: 위쳇페이 | O3: KB국민 | P3: NH농협 | Q3: 비씨 | R3: 현대 | S3: 신한 | T3: 삼성 | U3: 롯데 | V3: 합계
A4: 46082 | D4: =V4 -> 0 | F4: =+B4+D4+E4+C4 -> 0 | J4: =+B4-I4 -> 0 | V4: =SUM(M4:U4) -> 0
A5: 46083 | D5: =V5 -> 0 | F5: =+B5+D5+E5+C5 -> 0 | J5: =+B5-I5 -> 0 | V5: =SUM(M5:U5) -> 0
A6: 46084 | D6: =V6 -> 0 | F6: =+B6+D6+E6+C6 -> 0 | J6: =+B6-I6 -> 0 | V6: =SUM(M6:U6) -> 0
A7: 46085 | D7: =V7 -> 0 | F7: =+B7+D7+E7+C7 -> 0 | J7: =+B7-I7 -> 0 | V7: =SUM(M7:U7) -> 0
A8: 46086 | D8: =V8 -> 0 | F8: =+B8+D8+E8+C8 -> 0 | J8: =+B8-I8 -> 0 | V8: =SUM(M8:U8) -> 0
A9: 46087 | D9: =V9 -> 0 | F9: =+B9+D9+E9+C9 -> 0 | J9: =+B9-I9 -> 0 | V9: =SUM(M9:U9) -> 0
A10: 46088 | D10: =V10 -> 0 | F10: =+B10+D10+E10+C10 -> 0 | J10: =+B10-I10 -> 0 | V10: =SUM(M10:U10) -> 0
A11: 46089 | D11: =V11 -> 0 | F11: =+B11+D11+E11+C11 -> 0 | J11: =+B11-I11 -> 0 | V11: =SUM(M11:U11) -> 0
A12: 46090 | D12: =V12 -> 0 | F12: =+B12+D12+E12+C12 -> 0 | J12: =+B12-I12 -> 0 | V12: =SUM(M12:U12) -> 0
A13: 46091 | D13: =V13 -> 0 | F13: =+B13+D13+E13+C13 -> 0 | J13: =+B13-I13 -> 0 | V13: =SUM(M13:U13) -> 0
A14: 46092 | D14: =V14 -> 0 | F14: =+B14+D14+E14+C14 -> 0 | J14: =+B14-I14 -> 0 | V14: =SUM(M14:U14) -> 0
A15: 46093 | D15: =V15 -> 0 | F15: =+B15+D15+E15+C15 -> 0 | J15: =+B15-I15 -> 0 | V15: =SUM(M15:U15) -> 0
... A34: 46112 | D34: =V34 -> 0 | F34: =+B34+D34+E34+C34 -> 0 | J34: =+B34-I34 -> 0 | V34: =SUM(M34:U34) -> 0
A35: 합 계 | B35: =SUM(B4:B34) -> 0 | C35: =SUM(C4:C34) -> 0 | D35: =SUM(D4:D34) -> 0 | E35: =SUM(E4:E34) -> 0 | F35: =+B35+D35+E35 -> 0 | G35: =SUM(G4:G34) -> 0 | H35: =SUM(H4:H34) -> 0 | I35: =SUM(I4:I34) -> 0 | J35: =SUM(J4:J34) -> 0 | L35: =SUM(L4:L34) -> 0 | M35: =SUM(M4:M34) -> 0 | N35: =SUM(N4:N34) -> 0 | O35: =SUM(O4:O34) -> 0 | P35: =SUM(P4:P34) -> 0 | Q35: =SUM(Q4:Q34) -> 0 | R35: =SUM(R4:R34) -> 0 | S35: =SUM(S4:S34) -> 0 | ... V35: =SUM(V4:V34) -> 0
A38: 해외카드 결제분 있을 시, BC카드 가맹점 홈페이지 확인
A39: '오장동흥남집' : MRG 12,000천원 '24.4.1부터 적용
A40: 수수료율 | B40: 0.19 | D40: 최소
A41: 임대료 | B41: =ROUND(B43/1.1,0) -> 0 | D41: 12000000 | F41: 임대을매출 | G41: =+G35 -> 0 | H41: 임대을매출원가 | I41: =+B45 -> 0
A42: VAT | B42: =+B43-B41 -> 0 | D42: 1200000 | F42: 임대을매출원가 | G42: =+I41 -> 0 | H42: 임대을매출_할인 | I42: =B46 -> 0
A43: 합계 | B43: =+G35*B40 -> 0 | D43: =D41+D42 -> 13200000 | H43: 임대을매출_수수료 | I43: =B41 -> 0
H44: 예수부가세 | I44: =B42 -> 0
A45: 매출원가 | B45: =G35-B41 -> 0 | H45: 미지급금 | I45: =+B47 -> 0
A46: 할인 | B46: =F35 -> 0
A47: 미지급금 | B47: =E35+B35+D35-B43 -> 0 | D47: =I39-B43 -> 0 | G47: =SUM(G41:G46) -> 0 | I47: =SUM(I41:I46) -> 0
A49: * 당사 카드 단말기 사용 (국민 004-01-0415258 계좌)
A50: * 상품대지급일 (익월 10일까지) - 카드매출금에서 수수료 제외 후 입금
M57: 아 근데 저 유림이한테 뭐 한번 사야 되는데 금욜에 제가 둘다 한번에 살까요 그리고 그 담주에 하루 점심 가시죠 콜????????

Sheet 백년옥
B1: 지정에프앤비 | C1: 백년옥 | D1: 647-86-00540 | E1: 000540
M2: 1048656659 | N2: 119948 | O2: 033138 | P2: 007072 | Q2: 037726 | R2: 015419 | S2: 072014 | T2: 045602 | U2: 054231
A3: 일 자 | B3: 현금매출액 | C3: 전자화폐 | D3: 카드매출액 | E3: 할인액 | F3: 총매출액 | G3: 입금기한 | H3: 입금일 | I3: 입금액 | J3: 잔액 | K3: 연체일 | L3: 연체료 | M3: 하나 | N3: 위쳇페이 | O3: KB국민 | P3: NH농협 | Q3: 비씨 | R3: 현대 | S3: 신한 | T3: 삼성 | U3: 롯데 | V3: 합계
A4: 46082 | D4: =V4 -> 0 | F4: =+B4+D4+E4+C4 -> 0 | J4: =+B4-I4 -> 0 | V4: =SUM(M4:U4) -> 0
A5: 46083 | D5: =V5 -> 0 | F5: =+B5+D5+E5+C5 -> 0 | J5: =+B5-I5 -> 0 | V5: =SUM(M5:U5) -> 0
A6: 46084 | D6: =V6 -> 0 | F6: =+B6+D6+E6+C6 -> 0 | J6: =+B6-I6 -> 0 | V6: =SUM(M6:U6) -> 0
A7: 46085 | D7: =V7 -> 0 | F7: =+B7+D7+E7+C7 -> 0 | J7: =+B7-I7 -> 0 | V7: =SUM(M7:U7) -> 0
A8: 46086 | D8: =V8 -> 0 | F8: =+B8+D8+E8+C8 -> 0 | J8: =+B8-I8 -> 0 | V8: =SUM(M8:U8) -> 0
A9: 46087 | D9: =V9 -> 0 | F9: =+B9+D9+E9+C9 -> 0 | J9: =+B9-I9 -> 0 | V9: =SUM(M9:U9) -> 0
A10: 46088 | D10: =V10 -> 0 | F10: =+B10+D10+E10+C10 -> 0 | J10: =+B10-I10 -> 0 | V10: =SUM(M10:U10) -> 0
A11: 46089 | D11: =V11 -> 0 | F11: =+B11+D11+E11+C11 -> 0 | J11: =+B11-I11 -> 0 | V11: =SUM(M11:U11) -> 0
A12: 46090 | D12: =V12 -> 0 | F12: =+B12+D12+E12+C12 -> 0 | J12: =+B12-I12 -> 0 | V12: =SUM(M12:U12) -> 0
A13: 46091 | D13: =V13 -> 0 | F13: =+B13+D13+E13+C13 -> 0 | J13: =+B13-I13 -> 0 | V13: =SUM(M13:U13) -> 0
A14: 46092 | D14: =V14 -> 0 | F14: =+B14+D14+E14+C14 -> 0 | J14: =+B14-I14 -> 0 | V14: =SUM(M14:U14) -> 0
A15: 46093 | D15: =V15 -> 0 | F15: =+B15+D15+E15+C15 -> 0 | J15: =+B15-I15 -> 0 | V15: =SUM(M15:U15) -> 0
... A34: 46112 | D34: =V34 -> 0 | F34: =+B34+D34+E34+C34 -> 0 | J34: =+B34-I34 -> 0 | V34: =SUM(M34:U34) -> 0
A35: 합 계 | B35: =SUM(B4:B34) -> 0 | C35: =SUM(C4:C34) -> 0 | D35: =SUM(D4:D34) -> 0 | E35: =SUM(E4:E34) -> 0 | F35: =+B35+D35+E35 -> 0 | G35: =SUM(G4:G34) -> 0 | H35: =SUM(H4:H34) -> 0 | I35: =SUM(I4:I34) -> 0 | J35: =SUM(J4:J34) -> 0 | L35: =SUM(L4:L34) -> 0 | M35: =SUM(M4:M34) -> 0 | N35: =SUM(N4:N34) -> 0 | O35: =SUM(O4:O34) -> 0 | P35: =SUM(P4:P34) -> 0 | Q35: =SUM(Q4:Q34) -> 0 | R35: =SUM(R4:R34) -> 0 | S35: =SUM(S4:S34) -> 0 | ... V35: =SUM(V4:V34) -> 0
B37: 현금 입금 시작
A38: 해외카드 결제분 있을 시, BC카드 가맹점 홈페이지 확인
B39: 2024년4월1일부터 최저적용
A40: 수수료율 | B40: 0.19 | C40: 최저
A41: 임대료 | B41: =ROUND(B43/1.1,0) -> 0 | C41: 12000000 | E41: 임대을매출 | G41: =+F35 -> 0 | H41: 임대을매출원가 | I41: =+B45 -> 0
A42: VAT | B42: =+B43-B41 -> 0 | C42: 1200000 | E42: 임대을매출원가 | G42: =+I41 -> 0 | H42: 임대을매출_할인 | I42: =B46 -> 0
A43: 합계 | B43: =+F35*B40 -> 0 | C43: =C41+C42 -> 13200000 | H43: 임대을매출_수수료 | I43: =+B41 -> 0
H44: 예수부가세 | I44: =+B42 -> 0
A45: 매출원가 | B45: =F35-B41 -> 0 | H45: 미지급금 | I45: =+B47 -> 0
A46: 할인 | B46: =E35 -> 0 | I46: =B35 -> 0
A47: 미지급금 | B47: =D35+C35-B43+B35 -> 0 | G47: =SUM(G41:G46) -> 0 | I47: =SUM(I41:I46) -> 0
A49: * 당사 카드 단말기 사용 (국민 004-01-0415258 계좌)
A50: * 상품대지급일 (익월 10일까지) - 카드매출금에서 수수료 제외 후 입금
B52: 전자화폐 합계 | C52: =돈이찌!E35+중화가정!E35+가족회관!E35+땀땀!C35+오장동흥남집!D35+백년옥!C37 -> 0

Sheet 서리재
B1: ㈜삼천리이엔지 | C1: 서리재 | D1: 107-86-11651 | E1: 311652
M2: 1048656659 | N2: 119948 | O2: 033138 | P2: 007072 | Q2: 037726 | R2: 015419 | S2: 072014 | T2: 045602 | U2: 054231
A3: 일 자 | B3: 현금매출액 | C3: 전자화폐 | D3: 카드매출액 | E3: 할인액 | F3: 총매출액 | G3: 입금기한 | H3: 입금일 | I3: 입금액 | J3: 잔액 | K3: 연체일 | L3: 연체료 | M3: 하나 | N3: 위쳇페이 | O3: KB국민 | P3: NH농협 | Q3: 비씨 | R3: 현대 | S3: 신한 | T3: 삼성 | U3: 롯데 | V3: 합계
A4: 46082 | D4: =V4 -> 0 | F4: =+B4+D4+E4+C4 -> 0 | J4: =+B4-I4 -> 0 | V4: =SUM(M4:U4) -> 0
A5: 46083 | D5: =V5 -> 0 | F5: =+B5+D5+E5+C5 -> 0 | J5: =+B5-I5 -> 0 | V5: =SUM(M5:U5) -> 0
A6: 46084 | D6: =V6 -> 0 | F6: =+B6+D6+E6+C6 -> 0 | J6: =+B6-I6 -> 0 | V6: =SUM(M6:U6) -> 0
A7: 46085 | D7: =V7 -> 0 | F7: =+B7+D7+E7+C7 -> 0 | J7: =+B7-I7 -> 0 | V7: =SUM(M7:U7) -> 0
A8: 46086 | D8: =V8 -> 0 | F8: =+B8+D8+E8+C8 -> 0 | J8: =+B8-I8 -> 0 | V8: =SUM(M8:U8) -> 0
A9: 46087 | D9: =V9 -> 0 | F9: =+B9+D9+E9+C9 -> 0 | J9: =+B9-I9 -> 0 | V9: =SUM(M9:U9) -> 0
A10: 46088 | D10: =V10 -> 0 | F10: =+B10+D10+E10+C10 -> 0 | J10: =+B10-I10 -> 0 | V10: =SUM(M10:U10) -> 0
A11: 46089 | D11: =V11 -> 0 | F11: =+B11+D11+E11+C11 -> 0 | J11: =+B11-I11 -> 0 | V11: =SUM(M11:U11) -> 0
A12: 46090 | D12: =V12 -> 0 | F12: =+B12+D12+E12+C12 -> 0 | J12: =+B12-I12 -> 0 | V12: =SUM(M12:U12) -> 0
A13: 46091 | D13: =V13 -> 0 | F13: =+B13+D13+E13+C13 -> 0 | J13: =+B13-I13 -> 0 | V13: =SUM(M13:U13) -> 0
A14: 46092 | D14: =V14 -> 0 | F14: =+B14+D14+E14+C14 -> 0 | J14: =+B14-I14 -> 0 | V14: =SUM(M14:U14) -> 0
A15: 46093 | D15: =V15 -> 0 | F15: =+B15+D15+E15+C15 -> 0 | J15: =+B15-I15 -> 0 | V15: =SUM(M15:U15) -> 0
... A34: 46112 | D34: =V34 -> 0 | F34: =+B34+D34+E34+C34 -> 0 | J34: =+B34-I34 -> 0 | V34: =SUM(M34:U34) -> 0
A35: 합 계 | B35: =SUM(B4:B34) -> 0 | C35: =SUM(C4:C34) -> 0 | D35: =SUM(D4:D34) -> 0 | E35: =SUM(E4:E34) -> 0 | F35: =+B35+D35+E35 -> 0 | G35: =SUM(G4:G34) -> 0 | H35: =SUM(H4:H34) -> 0 | I35: =SUM(I4:I34) -> 0 | J35: =SUM(J4:J34) -> 0 | L35: =SUM(L4:L34) -> 0 | M35: =SUM(M4:M34) -> 0 | N35: =SUM(N4:N34) -> 0 | O35: =SUM(O4:O34) -> 0 | P35: =SUM(P4:P34) -> 0 | Q35: =SUM(Q4:Q34) -> 0 | R35: =SUM(R4:R34) -> 0 | S35: =SUM(S4:S34) -> 0 | ... V35: =SUM(V4:V34) -> 0
A37: 해외카드 결제분 있을 시, BC카드 가맹점 홈페이지 확인
A38: '서리재' : 매출 1.6억 이상 16.0% / 1.2억~1.6억 15.0% / 1.2억 미만 14.0%
A39: 수수료율 | B39: 0.16 | C39: 최저 | E39: 임대을매출 | F39: =+E35 -> 0 | G39: 임대을매출원가 | H39: =+B44 -> 0
A40: 임대료 | B40: =ROUND(B42/1.1,0) -> 0 | C40: 15000000 | E40: 임대을매출원가 | F40: =+H39 -> 0 | G40: 임대을매출_할인 | H40: =B45 -> 0
A41: VAT | B41: =+B42-B40 -> 0 | C41: 1500000 | G41: 임대을매출_수수료 | H41: =+B40 -> 0
A42: 합계 | B42: =+E35*B39 -> 0 | C42: =C40+C41 -> 16500000 | G42: 예수부가세 | H42: =+B41 -> 0
G43: 미지급금 | H43: =+B46 -> 0
A44: 매출원가 | B44: =E35-B40 -> 0
A45: 할인 | B45: =D35 -> 0 | F45: =SUM(F39:F44) -> 0 | H45: =SUM(H39:H44) -> 0
A46: 미지급금 | B46: =C35+B35-B42 -> 0
A48: * 당사 카드 단말기 사용 (국민 004-01-0415258 계좌)
A49: * 상품대지급일 (익월 10일까지) - 카드매출금에서 수수료 제외 후 입금

Sheet 호우섬
B1: ㈜삼천리이엔지 | C1: 호우섬 | D1: 107-86-11651 | E1: 211652
M2: 1048656659 | N2: 119948 | O2: 033138 | P2: 007072 | Q2: 037726 | R2: 015419 | S2: 072014 | T2: 045602 | U2: 054231
A3: 일 자 | B3: 현금매출액 | C3: 전자화폐 | D3: 카드매출액 | E3: 할인액 | F3: 총매출액 | G3: 입금기한 | H3: 입금일 | I3: 입금액 | J3: 잔액 | K3: 연체일 | L3: 연체료 | M3: 하나 | N3: 위쳇페이 | O3: KB국민 | P3: NH농협 | Q3: 비씨 | R3: 현대 | S3: 신한 | T3: 삼성 | U3: 롯데 | V3: 합계
A4: 46082 | D4: =V4 -> 0 | F4: =+B4+D4+E4+C4 -> 0 | J4: =+B4-I4 -> 0 | V4: =SUM(M4:U4) -> 0
A5: 46083 | D5: =V5 -> 0 | F5: =+B5+D5+E5+C5 -> 0 | J5: =+B5-I5 -> 0 | V5: =SUM(M5:U5) -> 0
A6: 46084 | D6: =V6 -> 0 | F6: =+B6+D6+E6+C6 -> 0 | J6: =+B6-I6 -> 0 | V6: =SUM(M6:U6) -> 0
A7: 46085 | D7: =V7 -> 0 | F7: =+B7+D7+E7+C7 -> 0 | J7: =+B7-I7 -> 0 | V7: =SUM(M7:U7) -> 0
A8: 46086 | D8: =V8 -> 0 | F8: =+B8+D8+E8+C8 -> 0 | J8: =+B8-I8 -> 0 | V8: =SUM(M8:U8) -> 0
A9: 46087 | D9: =V9 -> 0 | F9: =+B9+D9+E9+C9 -> 0 | J9: =+B9-I9 -> 0 | V9: =SUM(M9:U9) -> 0
A10: 46088 | D10: =V10 -> 0 | F10: =+B10+D10+E10+C10 -> 0 | J10: =+B10-I10 -> 0 | V10: =SUM(M10:U10) -> 0
A11: 46089 | D11: =V11 -> 0 | F11: =+B11+D11+E11+C11 -> 0 | J11: =+B11-I11 -> 0 | V11: =SUM(M11:U11) -> 0
